Workbook

Sheet 作品一覧
A1: 作品ID | B1: 作品名 | C1: 読み仮名
A2: aknk | B2: 悪魔執事と黒い猫 | C2: あ
A3: i7 | B3: アイドリッシュセブン | C3: あ
A4: enst | B4: あんさんぶるスターズ！！ | C4: あ
A5: aopl | B5: アオペラ -aoppella!?- | C5: あ
A6: aichu | B6: アイ★チュウ | C6: あ
A7: sM | B7: アイドルマスター SideM | C7: あ
A8: ACTORS | B8: ACTORS | C8: あ
A9: akay | B9: 悪魔王子と操り人形 | C9: あ
A10: and0 | B10: &0 | C10: あ
A11: anmn | B11: アンジェリーク ルミナライズ | C11: あ
A12: ikesen | B12: イケメン戦国 時をかける恋 | C12: い
... A92: rikm | B92: ライドカメンズ | C92: ら

Sheet 声優一覧
A1: 声優ID | B1: 声優名 | C1: 声優一覧に表示 | D1: 定番声優に表示 | E1: 出演作品数 | F1: 代表作 | G1: サンプルボイスURL | H1: 表記
A2: ="va_" & TEXT(ROW(A1), "000") -> va_001 | B2: 赤澤燈 | C2: F | D2: =IF(E2="", "", IF(E2>=3, "表示", "非表示")) -> 非表示 | E2: =IFERROR(__xludf.DUMMYFUNCTION("MAP(B2:B1000, LAMBDA(name, IF(name="""", """", COUNTA(UNIQUE(FILTER('キャラクター名'!C:C, 'キャラクター名'!B:B=name)))))) "),1) -> 1
A3: ="va_" & TEXT(ROW(A2), "000") -> va_002 | B3: 赤羽根健治 | C3: T | D3: =IF(E3="", "", IF(E3>=3, "表示", "非表示")) -> 表示 | E3: =IFERROR(__xludf.DUMMYFUNCTION("""COMPUTED_VALUE"""),5) -> 5 | F3: • 『真マジンガー 衝撃! Z編』：兜甲児 • 『THE IDOLM@STER』：プロデューサー • 『ジュエルペット てぃんくる☆』：レオン • 『宇崎ちゃんは遊びたい！』：桜井真一 • 『世界最高の暗殺者、異世界貴族に転生する』：ルーグ | G3: https://www.aoni.co.jp/search/akabane-kenji.html | H3: Voice Sample
A4: ="va_" & TEXT(ROW(A3), "000") -> va_003 | B4: 阿座上洋平 | C4: T | D4: =IF(E4="", "", IF(E4>=3, "表示", "非表示")) -> 表示 | E4: =IFERROR(__xludf.DUMMYFUNCTION("""COMPUTED_VALUE"""),11) -> 11 | F4: • 『機動戦士ガンダム 水星の魔女』：グエル・ジェターク • 『あんさんぶるスターズ！！』：天城燐音 • 『クロムクロ』：青馬剣之介時貞 • 『鴨乃橋ロンの禁断推理』：鴨乃橋ロン | G4: https://www.aoni.co.jp/search/azakami-yohei.html | H4: Voice Sample
A5: ="va_" & TEXT(ROW(A4), "000") -> va_004 | B5: 浅沼晋太郎 | C5: T | D5: =IF(E5="", "", IF(E5>=3, "表示", "非表示")) -> 表示 | E5: =IFERROR(__xludf.DUMMYFUNCTION("""COMPUTED_VALUE"""),10) -> 10 | F5: • 『ヒプノシスマイク』：碧棺左馬刻 • 『あんさんぶるスターズ！』：月永レオ • 『生徒会役員共』：津田タカトシ • 『ダイヤのA』：倉持洋一 • 『ギヴン』：村田雨月
A6: ="va_" & TEXT(ROW(A5), "000") -> va_005 | B6: 浅利遼太 | C6: T | D6: =IF(E6="", "", IF(E6>=3, "表示", "非表示")) -> 非表示 | E6: =IFERROR(__xludf.DUMMYFUNCTION("""COMPUTED_VALUE"""),2) -> 2 | F6: • 『刀剣乱舞』：平野藤四郎／明石国行／ソハヤノツルキ • 『ワールドトリガー』：小荒井登 • 『D.Gray-man HALLOW』：アルマ＝カルマ • 『妖怪ウォッチ』：砂夫／土蜘蛛 • 『呪術廻戦』：新田新 | G6: https://www.kenproduction.co.jp/talent/3 | H6: セリフ
A7: ="va_" & TEXT(ROW(A6), "000") -> va_006 | B7: 阿部敦 | C7: T | D7: =IF(E7="", "", IF(E7>=3, "表示", "非表示")) -> 表示 | E7: =IFERROR(__xludf.DUMMYFUNCTION("""COMPUTED_VALUE"""),7) -> 7 | F7: • 『とある魔術の禁書目録』／『とある科学の超電磁砲』：上条当麻 • 『バクマン。』：真城最高 • 『アイドリッシュセブン』：逢坂壮五 • 『しゅごキャラ！』：相馬空海 • 『弱虫ペダル』：泉田塔一郎 | G7: https://www.kenproduction.co.jp/talent/249 | H7: セリフ
A8: ="va_" & TEXT(ROW(A7), "000") -> va_007 | B8: 天﨑滉平 | C8: T | D8: =IF(E8="", "", IF(E8>=3, "表示", "非表示")) -> 表示 | E8: =IFERROR(__xludf.DUMMYFUNCTION("""COMPUTED_VALUE"""),11) -> 11 | F8: • 『ヒプノシスマイク』：山田三郎 • 『Re:ゼロから始める異世界生活』：オットー・スーウェン • 『ハイスコアガール』：矢口春雄 • 『僕のヒーローアカデミア』：物間寧人 • 『あんさんぶるスターズ！！』：白鳥藍良 | G8: https://www.imenterprise.jp/profile.php?id=11 | H8: ボイスサンプル
A9: ="va_" & TEXT(ROW(A8), "000") -> va_008 | B9: 天月 | C9: F | D9: =IF(E9="", "", IF(E9>=3, "表示", "非表示")) -> 表示 | E9: =IFERROR(__xludf.DUMMYFUNCTION("""COMPUTED_VALUE"""),3) -> 3
A10: ="va_" & TEXT(ROW(A9), "000") -> va_009 | B10: 蒼井翔太 | C10: T | D10: =IF(E10="", "", IF(E10>=3, "表示", "非表示")) -> 表示 | E10: =IFERROR(__xludf.DUMMYFUNCTION("""COMPUTED_VALUE"""),17) -> 17 | F10: • 『うたの☆プリンスさまっ♪』：美風藍 • 『KING OF PRISM』：如月ルヰ • 『乙女ゲームの破滅フラグしかない悪役令嬢に転生してしまった…』：ジオルド・スティアート • 『ツキウタ。』：水無月涙 • 『ヴィジュアルプリズン』：ハイド・ジャイエ
A11: ="va_" & TEXT(ROW(A10), "000") -> va_010 | B11: 相葉裕樹 | C11: F | D11: =IF(E11="", "", IF(E11>=3, "表示", "非表示")) -> 非表示 | E11: =IFERROR(__xludf.DUMMYFUNCTION("""COMPUTED_VALUE"""),1) -> 1
A12: ="va_" & TEXT(ROW(A11), "000") -> va_011 | B12: 五十嵐雅 | C12: F | D12: =IF(E12="", "", IF(E12>=3, "表示", "非表示")) -> 非表示 | E12: =IFERROR(__xludf.DUMMYFUNCTION("""COMPUTED_VALUE"""),2) -> 2
A13: ="va_" & TEXT(ROW(A12), "000") -> va_012 | B13: 井口祐一 | C13: T | D13: =IF(E13="", "", IF(E13>=3, "表示", "非表示")) -> 表示 | E13: =IFERROR(__xludf.DUMMYFUNCTION("""COMPUTED_VALUE"""),5) -> 5 | F13: • 『僕らはみんな河合荘』：宇佐和成 • 『はたらく魔王さま！』：猿江三月／サリエル • 『FAIRY TAIL』：マックス • 『Spiritpact』：楊敬華 • 『BEASTARS』：キビ | G13: https://haikyo.co.jp/profile/profile.php?ActorID=12183 | H13: ボイスサンプル
A14: ="va_" & TEXT(ROW(A13), "000") -> va_013 | B14: 石川界人 | C14: T | D14: =IF(E14="", "", IF(E14>=3, "表示", "非表示")) -> 表示 | E14: =IFERROR(__xludf.DUMMYFUNCTION("""COMPUTED_VALUE"""),15) -> 15 | F14: • 『ハイキュー!!』：影山飛雄 • 『ワンパンマン』：ジェノス • 『僕のヒーローアカデミア』：飯田天哉 • 『盾の勇者の成り上がり』：岩谷尚文 • 『青春ブタ野郎シリーズ』：梓川咲太 • 『わたしの幸せな結婚』：久堂清霞 | G14: https://stay-luck.com/talent/ishikawa-kaito/ | H14: Voice Sample
A15: ="va_" & TEXT(ROW(A14), "000") -> va_014 | B15: 石谷春貴 | C15: T | D15: =IF(E15="", "", IF(E15>=3, "表示", "非表示")) -> 表示 | E15: =IFERROR(__xludf.DUMMYFUNCTION("""COMPUTED_VALUE"""),8) -> 8 | F15: • 『響け！ユーフォニアム』：塚本秀一 • 『ヒプノシスマイク』：山田二郎 • 『AKIBA’S TRIP -THE ANIMATION-』：伝木凱タモツ • 『ぼくたちのリメイク』：鹿苑寺貫之 • 『この音とまれ！』：足立実康 | G15: https://osawa-inc.co.jp/men/ishiyaharuki/ | H15: ボイスサンプル
A16: ="va_" & TEXT(ROW(A15), "000") -> va_015 | B16: 市川蒼 | C16: T | D16: =IF(E16="", "", IF(E16>=3, "表示", "非表示")) -> 非表示 | E16: =IFERROR(__xludf.DUMMYFUNCTION("""COMPUTED_VALUE"""),2) -> 2 | F16: • 『Just Because!』：泉瑛太 • 『ダーリン・イン・ザ・フランキス』：ミツル • 『ツルネ ―風舞高校弓道部―』：竹早静弥 • 『ブルーロック』：五十嵐栗夢 • 『地獄楽』：山田浅ェ門付知 • 『ディズニー ツイステッドワンダーランド』：ラギー・ブッチ | G16: https://osawa-inc.co.jp/men/ichikawaaoi/ | H16: ボイスサンプル
A17: ="va_" & TEXT(ROW(A16), "000") -> va_016 | B17: 市川太一 | C17: T | D17: =IF(E17="", "", IF(E17>=3, "表示", "非表示")) -> 非表示 | E17: =IFERROR(__xludf.DUMMYFUNCTION("""COMPUTED_VALUE"""),2) -> 2 | F17: • 『カブキブ！』：来栖黒悟 • 『やがて君になる』：槙聖司 • 『終末のハーレム』：水原怜人 • 『時々ボソッとロシア語でデレる隣のアーリャさん』：清宮光瑠 | G17: https://www.vims.co.jp/talent/327/ | H17: VOICE SAMPLE
A18: ="va_" & TEXT(ROW(A17), "000") -> va_017 | B18: 市来光弘 | C18: T | D18: =IF(E18="", "", IF(E18>=3, "表示", "非表示")) -> 非表示 | E18: =IFERROR(__xludf.DUMMYFUNCTION("""COMPUTED_VALUE"""),2) -> 2 | F18: • 『刀剣乱舞』：大和守安定 • 『スクールランブル』：麻生広義 • 『会長はメイド様！』：白川直也 • 『ドロヘドロ』：カスカベ • 『佐々木と宮野』：田代権三郎 • 『八十亀ちゃんかんさつにっき』：陣界斗 | G18: https://mausu.net/talent/ichiki-mitsuhiro.html
A19: ="va_" & TEXT(ROW(A18), "000") -> va_018 | B19: 伊藤マサミ | C19: F | D19: =IF(E19="", "", IF(E19>=3, "表示", "非表示")) -> 非表示 | E19: =IFERROR(__xludf.DUMMYFUNCTION("""COMPUTED_VALUE"""),1) -> 1
A20: ="va_" & TEXT(ROW(A19), "000") -> va_019 | B20: 伊東健人 | C20: T | D20: =IF(E20="", "", IF(E20>=3, "表示", "非表示")) -> 表示 | E20: =IFERROR(__xludf.DUMMYFUNCTION("""COMPUTED_VALUE"""),14) -> 14 | F20: • 『ヲタクに恋は難しい』：二藤宏嵩 • 『【推しの子】』：ゴロー • 『ヒプノシスマイク』：観音坂独歩 • 『アイドルマスター SideM』：硲道夫 • 『プロジェクトセカイ カラフルステージ！』：青柳冬弥 | G20: https://www.81produce.co.jp/dcms_plusdb/index.php/item?cell003=%E3%81%82%E8%A1%8C&keyword=&cell028=&page=2&cell004=&name=%E4%BC%8A%E6%9D%B1%E3%80%80%E5%81%A5%E4%BA%BA&id=9&label=1 | H20: Voice Sample
A21: ="va_" & TEXT(ROW(A20), "000") -> va_020 | B21: 糸川耀士郎 | C21: F | D21: =IF(E21="", "", IF(E21>=3, "表示", "非表示")) -> 非表示 | E21: =IFERROR(__xludf.DUMMYFUNCTION("""COMPUTED_VALUE"""),1) -> 1
A22: ="va_" & TEXT(ROW(A21), "000") -> va_021 | B22: 井上和彦 | C22: T | D22: =IF(E22="", "", IF(E22>=3, "表示", "非表示")) -> 表示 | E22: =IFERROR(__xludf.DUMMYFUNCTION("""COMPUTED_VALUE"""),5) -> 5 | F22: • 『NARUTO -ナルト-』：はたけカカシ • 『夏目友人帳』：ニャンコ先生／斑 • 『美味しんぼ』：山岡士郎 • 『サイボーグ009』：島村ジョー • 『機動戦士Ζガンダム』：ジェリド・メサ • 『名探偵コナン』：白鳥任三郎 | G22: https://b-box-box.com/actor/kazuhiko_inoue/ | H22: VOICE SAMPLE
A23: ="va_" & TEXT(ROW(A22), "000") -> va_022 | B23: 井上雄貴 | C23: T | D23: =IF(E23="", "", IF(E23>=3, "表示", "非表示")) -> 表示 | E23: =IFERROR(__xludf.DUMMYFUNCTION("""COMPUTED_VALUE"""),3) -> 3 | F23: • 『天使の3P!』：貫井響 • 『かくりよの宿飯』：サスケ • 『アトム ザ・ビギニング』：A106 • 『月刊モー想科学』：ノイン • 『ハイキュー!!』：姫川葵 | G23: https://mausu.net/talent/inoue-yuki.html
A24: ="va_" & TEXT(ROW(A23), "000") -> va_023 | B24: 今井文也 | C24: T | D24: =IF(E24="", "", IF(E24>=3, "表示", "非表示")) -> 表示 | E24: =IFERROR(__xludf.DUMMYFUNCTION("""COMPUTED_VALUE"""),7) -> 7 | F24: • 『ギヴン』：鹿島柊 • 『神クズ☆アイドル』：仁淀ユウヤ • 『プロジェクトセカイ カラフルステージ！』：東雲彰人 • 『ハナビちゃんは遅れがち』：東雲ムサシ • 『A3!』：木之崎レント | G24: https://rushstyle.net/talent/fumiya_imai/ | H24: Voice Sample
A25: ="va_" & TEXT(ROW(A24), "000") -> va_024 | B25: 入江玲於奈 | C25: T | D25: =IF(E25="", "", IF(E25>=3, "表示", "非表示")) -> 非表示 | E25: =IFERROR(__xludf.DUMMYFUNCTION("""COMPUTED_VALUE"""),1) -> 1 | F25: • 『刀剣乱舞』：前田藤四郎 • 『プリンスPiaキャロット』：立花心路 • 『でみめん』：サタン • 『乙女剣武蔵』：宍戸梅軒 | G25: https://www.atomicmonkey.jp/talent/iriereona | H25: クレジット
A26: ="va_" & TEXT(ROW(A25), "000") -> va_025 | B26: 入野自由 | C26: T | D26: =IF(E26="", "", IF(E26>=3, "表示", "非表示")) -> 表示 | E26: =IFERROR(__xludf.DUMMYFUNCTION("""COMPUTED_VALUE"""),3) -> 3 | F26: • 『おそ松さん』：松野トド松 • 『ハイキュー!!』：菅原孝支 • 『千と千尋の神隠し』：ハク • 『キングダム ハーツ』：ソラ • 『アイシールド21』：小早川瀬那 • 『あの日見た花の名前を僕達はまだ知らない。』：宿海仁太
A27: ="va_" & TEXT(ROW(A26), "000") -> va_026 | B27: 岩崎諒太 | C27: T | D27: =IF(E27="", "", IF(E27>=3, "表示", "非表示")) -> 表示 | E27: =IFERROR(__xludf.DUMMYFUNCTION("""COMPUTED_VALUE"""),3) -> 3 | F27: • 『ヒプノシスマイク』：白膠木簓 • 『僕のヒーローアカデミア』：夜嵐イナサ • 『ザ・ファブル』：黒塩遼 • 『柚木さんちの四兄弟。』：柚木隼 • 『からくりサーカス』：仲町紀之 | G27: https://www.atomicmonkey.jp/talent/iwasakiryouta | H27: セリフ01
A28: ="va_" & TEXT(ROW(A27), "000") -> va_027 | B28: 岩中睦樹 | C28: T | D28: =IF(E28="", "", IF(E28>=3, "表示", "非表示")) -> 非表示 | E28: =IFERROR(__xludf.DUMMYFUNCTION("""COMPUTED_VALUE"""),2) -> 2 | F28: • 『月がきれい』：立花大輔 • 『ようこそ実力至上主義の教室へ』：山内春樹 • 『キャプテン翼』：井沢守 • 『AIの遺電子』：ジェイ • 『ネガポジアングラー』：佐々木常宏 • 『妻、小学生になる。』：愛川蓮司 | G28: https://mausu.net/talent/iwanaka-mutsuki.html
A29: ="va_" & TEXT(ROW(A28), "000") -> va_028 | B29: 上村祐翔 | C29: T | D29: =IF(E29="", "", IF(E29>=3, "表示", "非表示")) -> 表示 | E29: =IFERROR(__xludf.DUMMYFUNCTION("""COMPUTED_VALUE"""),11) -> 11 | F29: • 『文豪ストレイドッグス』：中島敦 • 『ダーリン・イン・ザ・フランキス』：ヒロ • 『僕のヒーローアカデミア』：天喰環 • 『ヴィンランド・サガ』：トルフィン • 『ツルネ ―風舞高校弓道部―』：鳴宮湊 • 『B-PROJECT』：増長和南
A30: ="va_" & TEXT(ROW(A29), "000") -> va_029 | B30: 内田修一 | C30: T | D30: =IF(E30="", "", IF(E30>=3, "表示", "非表示")) -> 非表示 | E30: =IFERROR(__xludf.DUMMYFUNCTION("""COMPUTED_VALUE"""),1) -> 1 | F30: • 『灼熱カバディ』：栄倉祐 • 『カミエラビ GOD.app』：秋津豊 • 『転生貴族、鑑定スキルで成り上がる』：ブラッハム・ジョー • 『その着せ替え人形は恋をする』：森田健星 • 『夫婦以上、恋人未満。』：寺船周 • 『アンダーニンジャ』：瑛太 | G30: https://intention-k.com/profile/shuichi_uchida | H30: UCHIDA
A31: ="va_" & TEXT(ROW(A30), "000") -> va_030 | B31: 内田雄馬 | C31: T | D31: =IF(E31="", "", IF(E31>=3, "表示", "非表示")) -> 表示 | E31: =IFERROR(__xludf.DUMMYFUNCTION("""COMPUTED_VALUE"""),21) -> 21 | F31: • 『呪術廻戦』：伏黒恵 • 『BANANA FISH』：アッシュ・リンクス • 『ブルーロック』：御影玲王 • 『WIND BREAKER』：桜遥 • 『フルーツバスケット』：草摩夾 • 『マクロスΔ』：ハヤテ・インメルマン • 『りゅうおうのおしごと！』：九頭竜八一 | G31: https://intention-k.com/profile/yuma_uchida | H31: UCHIDA
A32: ="va_" & TEXT(ROW(A31), "000") -> va_031 | B32: 内山昂輝 | C32: T | D32: =IF(E32="", "", IF(E32>=3, "表示", "非表示")) -> 表示 | E32: =IFERROR(__xludf.DUMMYFUNCTION("""COMPUTED_VALUE"""),3) -> 3 | F32: • 『ハイキュー!!』：月島蛍 • 『僕のヒーローアカデミア』：死柄木弔 • 『呪術廻戦』：狗巻棘 • 『機動戦士ガンダムUC』：バナージ・リンクス • 『Free!』：桐嶋郁弥 • 『キングダム ハーツ』：ロクサス／ヴェントゥス • 『ホリミヤ』：宮村伊澄
A33: ="va_" & TEXT(ROW(A32), "000") -> va_032 | B33: 梅田修一朗 | C33: T | D33: =IF(E33="", "", IF(E33>=3, "表示", "非表示")) -> 表示 | E33: =IFERROR(__xludf.DUMMYFUNCTION("""COMPUTED_VALUE"""),3) -> 3 | F33: • 『可愛いだけじゃない式守さん』：和泉くん • 『魔法使い黎明期』：セービル • 『ゾンビ100～ゾンビになるまでにしたい100のこと～』：天道輝 • 『負けヒロインが多すぎる！』：温水和彦 • 『光が死んだ夏』：ヒカル • 『ヴィジランテ -僕のヒーローアカデミア ILLEGALS-』：灰廻航一 | G33: https://www.kenproduction.co.jp/talent/192 | H33: セリフ
A34: ="va_" & TEXT(ROW(A33), "000") -> va_033 | B34: 梅原裕一郎 | C34: T | D34: =IF(E34="", "", IF(E34>=3, "表示", "非表示")) -> 表示 | E34: =IFERROR(__xludf.DUMMYFUNCTION("""COMPUTED_VALUE"""),21) -> 21 | F34: • 『ゴブリンスレイヤー』：ゴブリンスレイヤー • 『美男高校地球防衛部LOVE!』：由布院煙 • 『あんさんぶるスターズ！』：蓮巳敬人 • 『アイドルマスター SideM』：鷹城恭二 • 『魔王学院の不適合者』：アノス・ヴォルディゴード • 『WIND BREAKER』：十亀条 • 『ディズニー ツイステッドワンダーランド』：レオナ・キングスカラー | G34: https://www.artsvision.co.jp/talent/14239/ | H34: ボイスサンプル
A35: ="va_" & TEXT(ROW(A34), "000") -> va_034 | B35: 浦和希 | C35: T | D35: =IF(E35="", "", IF(E35>=3, "表示", "非表示")) -> 表示 | E35: =IFERROR(__xludf.DUMMYFUNCTION("""COMPUTED_VALUE"""),4) -> 4 | F35: • 『ブルーロック』：潔世一 • 『シャドウバースF』：真壁スバル • 『テクノロイド オーバーマインド』：コバルト • 『桃源暗鬼』：一ノ瀬四季 • 『カミエラビ GOD.app』：ゴロー • 『悪魔執事と黒い猫』：ナック・シュタイン | G35: https://www.vims.co.jp/talent/329/ | H35: VOICE SAMPLE
A36: ="va_" & TEXT(ROW(A35), "000") -> va_035 | B36: 江口拓也 | C36: T | D36: =IF(E36="", "", IF(E36>=3, "表示", "非表示")) -> 表示 | E36: =IFERROR(__xludf.DUMMYFUNCTION("""COMPUTED_VALUE"""),20) -> 20 | F36: • 『SPY×FAMILY』：ロイド・フォージャー • 『やはり俺の青春ラブコメはまちがっている。』：比企谷八幡 • 『アイドリッシュセブン』：六弥ナギ • 『東京リベンジャーズ』：半間修二 • 『転生したらスライムだった件』：ソウエイ • 『マッシュル-MASHLE-』：ドット・バレット • 『あんさんぶるスターズ！』：日々樹渉 | G36: https://www.81produce.co.jp/dcms_plusdb/index.php/item?cell003=%E3%81%82%E8%A1%8C&label=1&page=3&cell004=&name=%E6%B1%9F%E5%8F%A3%E3%80%80%E6%8B%93%E4%B9%9F&id=18 | H36: Voice Sample
A37: ="va_" & TEXT(ROW(A36), "000") -> va_036 | B37: 榎木淳弥 | C37: T | D37: =IF(E37="", "", IF(E37>=3, "表示", "非表示")) -> 表示 | E37: =IFERROR(__xludf.DUMMYFUNCTION("""COMPUTED_VALUE"""),10) -> 10 | F37: • 『呪術廻戦』：虎杖悠仁 • 『ジョジョの奇妙な冒険 黄金の風』：パンナコッタ・フーゴ • 『トニカクカワイイ』：由崎星空 • 『アイドルマスター SideM』：舞田類 • 『め組の大吾 救国のオレンジ』：十朱大吾 | G37: https://asleben.jp/talents/junya-enoki | H37: Voice Sample
A38: ="va_" & TEXT(ROW(A37), "000") -> va_037 | B38: 逢坂良太 | C38: T | D38: =IF(E38="", "", IF(E38>=3, "表示", "非表示")) -> 表示 | E38: =IFERROR(__xludf.DUMMYFUNCTION("""COMPUTED_VALUE"""),14) -> 14 | F38: • 『ダイヤのA』：沢村栄純 • 『はたらく魔王さま！』：真奥貞夫（魔王サタン） • 『ハイキュー!!』：赤葦京治 • 『あんさんぶるスターズ！！』：七種茨 • 『赤髪の白雪姫』：ゼン • 『進撃の巨人』：マルコ・ボット • 『鬼滅の刃』：妓夫太郎 | G38: https://www.earlywing.co.jp/actordb/catea/talent_osakaryota | H38: Voice Sample
A39: ="va_" & TEXT(ROW(A38), "000") -> va_038 | B39: 小笠原仁 | C39: T | D39: =IF(E39="", "", IF(E39>=3, "表示", "非表示")) -> 表示 | E39: =IFERROR(__xludf.DUMMYFUNCTION("""COMPUTED_VALUE"""),6) -> 6 | F39: • 『from ARGONAVIS』：旭那由多 • 『カードファイト!! ヴァンガード will+Dress』：狐芝ライカ • 『WAVE!!～サーフィンやっぺ!!～』：秋月ショウ • 『カワイスギクライシス』：向井誠二 • 『18TRIP』：西園練牙 • 『SSSS.DYNAZENON』：淡木 | G39: https://www.earlywing.co.jp/actordb/catea/talent_ogasawarajin | H39: Voice Sample
A40: ="va_" & TEXT(ROW(A39), "000") -> va_039 | B40: 大須賀純 | C40: T | D40: =IF(E40="", "", IF(E40>=3, "表示", "非表示")) -> 表示 | E40: =IFERROR(__xludf.DUMMYFUNCTION("""COMPUTED_VALUE"""),4) -> 4 | F40: • 『あんさんぶるスターズ！』：影片みか • 『刀剣乱舞』：博多藤四郎 • 『新テニスの王子様』：千歳千里 • 『サンリオ男子』：吉野俊介 • 『おおきく振りかぶって』：叶修悟 • 『PJベリーのもぐもぐむにゃむにゃ』：PJベリー | G40: https://amuleto.jp/talents/osuka-jun.html | H40: フルボイス
...

Sheet 声優50音順
A1: 声優名 | B1: 読み仮名
A2: 赤羽根健治 | B2: あかばねけんじ
A3: 阿座上洋平 | B3: あざかみようへい
A4: 浅沼晋太郎 | B4: あさぬましんたろう
A5: 浅利遼太 | B5: あさりりょうた
A6: 阿部敦 | B6: あべあつし
A7: 天﨑滉平 | B7: あまさきこうへい
A8: 蒼井翔太 | B8: あおいしょうた
A9: 井口祐一 | B9: いぐちゆういち
A10: 石川界人 | B10: いしかわかいと
A11: 石谷春貴 | B11: いしやはるき
A12: 市川蒼 | B12: いちかわあおい
... A360: 小池貴大 | B360: こいけたかひろ

Sheet 定番声優一覧
A1: 声優ID | B1: 声優名 | C1: 声優一覧に表示 | D1: 定番声優に表示 | E1: 出演作品数
A2: =IFERROR(__xludf.DUMMYFUNCTION("SORT(FILTER('声優一覧'!A2:F1001, ( ('声優一覧'!D2:D1001=""表示"") * ('声優一覧'!C2:C1001<>""F"") ) + ISNUMBER(MATCH('声優一覧'!B2:B1001, {}, 0))), 5, FALSE) "),"va_083") -> va_083 | B2: =IFERROR(__xludf.DUMMYFUNCTION("""COMPUTED_VALUE"""),"斉藤壮馬") -> 斉藤壮馬 | C2: =IFERROR(__xludf.DUMMYFUNCTION("""COMPUTED_VALUE"""),"T") -> T | D2: =IFERROR(__xludf.DUMMYFUNCTION("""COMPUTED_VALUE"""),"表示") -> 表示 | E2: =IFERROR(__xludf.DUMMYFUNCTION("""COMPUTED_VALUE"""),27) -> 27 | F2: =IFERROR(__xludf.DUMMYFUNCTION("""COMPUTED_VALUE"""),"• 『ヒプノシスマイク』：夢野幻太郎 • 『アイドリッシュセブン』：九条天 • 『るろうに剣心 -明治剣客浪漫譚-』：緋村剣心 • 『ブルーロック』：千切豹馬 • 『ハイキュー!!』：山口忠 • 『刀剣乱舞』：鶴丸国永 • 『あんさんぶるスターズ！』：葵ひなた／葵ゆうた") -> • 『ヒプノシスマイク』：夢野幻太郎 • 『アイドリッシュセブン』：九条天 • 『るろうに剣心 -明治剣客浪漫譚-』：緋村剣心 • 『ブルーロック』：千切豹馬 • 『ハイキュー!!』：山口忠 • 『刀剣乱舞』：鶴丸国永 • 『あんさんぶるスターズ！』：葵ひなた／葵ゆうた
A3: =IFERROR(__xludf.DUMMYFUNCTION("""COMPUTED_VALUE"""),"va_161") -> va_161 | B3: =IFERROR(__xludf.DUMMYFUNCTION("""COMPUTED_VALUE"""),"古川慎") -> 古川慎 | C3: =IFERROR(__xludf.DUMMYFUNCTION("""COMPUTED_VALUE"""),"T") -> T | D3: =IFERROR(__xludf.DUMMYFUNCTION("""COMPUTED_VALUE"""),"表示") -> 表示 | E3: =IFERROR(__xludf.DUMMYFUNCTION("""COMPUTED_VALUE"""),25) -> 25 | F3: =IFERROR(__xludf.DUMMYFUNCTION("""COMPUTED_VALUE"""),"• 『ワンパンマン』： サイタマ • 『かぐや様は告らせたい〜天才たちの恋愛頭脳戦〜』： 白銀御行 • 『転生したらスライムだった件』： ベニマル • 『憂国のモリアーティ』： シャーロック・ホームズ • 『ゴールデンタイム』： 多田万里 • 『吸血鬼すぐ死ぬ』： ロナルド • 『機動戦士ガンダム 水星の魔女』： シャディク・ゼネリ") -> • 『ワンパンマン』： サイタマ • 『かぐや様は告らせたい〜天才たちの恋愛頭脳戦〜』： 白銀御行 • 『転生したらスライムだった件』： ベニマル • 『憂国のモリアーティ』： シャーロック・ホームズ • 『ゴールデンタイム』： 多田万里 • 『吸血鬼すぐ死ぬ』： ロナルド • 『機動戦士ガンダム 水星の魔女』： シャディク・ゼネリ
A4: =IFERROR(__xludf.DUMMYFUNCTION("""COMPUTED_VALUE"""),"va_048") -> va_048 | B4: =IFERROR(__xludf.DUMMYFUNCTION("""COMPUTED_VALUE"""),"柿原徹也") -> 柿原徹也 | C4: =IFERROR(__xludf.DUMMYFUNCTION("""COMPUTED_VALUE"""),"T") -> T | D4: =IFERROR(__xludf.DUMMYFUNCTION("""COMPUTED_VALUE"""),"表示") -> 表示 | E4: =IFERROR(__xludf.DUMMYFUNCTION("""COMPUTED_VALUE"""),23) -> 23 | F4: =IFERROR(__xludf.DUMMYFUNCTION("""COMPUTED_VALUE"""),"• 『FAIRY TAIL』：ナツ・ドラグニル • 『天元突破グレンラガン』：シモン • 『弱虫ペダル』：東堂尽八 • 『青の祓魔師』：アマイモン • 『B-PROJECT』：音済百太郎 • 『ツキウタ。』：葉月陽") -> • 『FAIRY TAIL』：ナツ・ドラグニル • 『天元突破グレンラガン』：シモン • 『弱虫ペダル』：東堂尽八 • 『青の祓魔師』：アマイモン • 『B-PROJECT』：音済百太郎 • 『ツキウタ。』：葉月陽
A5: =IFERROR(__xludf.DUMMYFUNCTION("""COMPUTED_VALUE"""),"va_169") -> va_169 | B5: =IFERROR(__xludf.DUMMYFUNCTION("""COMPUTED_VALUE"""),"前野智昭") -> 前野智昭 | C5: =IFERROR(__xludf.DUMMYFUNCTION("""COMPUTED_VALUE"""),"T") -> T | D5: =IFERROR(__xludf.DUMMYFUNCTION("""COMPUTED_VALUE"""),"表示") -> 表示 | E5: =IFERROR(__xludf.DUMMYFUNCTION("""COMPUTED_VALUE"""),23) -> 23 | F5: =IFERROR(__xludf.DUMMYFUNCTION("""COMPUTED_VALUE"""),"• 『図書館戦争』：堂上篤 • 『うたの☆プリンスさまっ♪』：カミュ • 『KING OF PRISM』：速水ヒロ • 『はたらく細胞』：白血球（好中球） • 『転生したらスライムだった件』：ヴェルドラ • 『原神』：鍾離 • 『暁のヨナ』：ソン・ハク • 『刀剣乱舞』：山姥切国広") -> • 『図書館戦争』：堂上篤 • 『うたの☆プリンスさまっ♪』：カミュ • 『KING OF PRISM』：速水ヒロ • 『はたらく細胞』：白血球（好中球） • 『転生したらスライムだった件』：ヴェルドラ • 『原神』：鍾離 • 『暁のヨナ』：ソン・ハク • 『刀剣乱舞』：山姥切国広
A6: =IFERROR(__xludf.DUMMYFUNCTION("""COMPUTED_VALUE"""),"va_030") -> va_030 | B6: =IFERROR(__xludf.DUMMYFUNCTION("""COMPUTED_VALUE"""),"内田雄馬") -> 内田雄馬 | C6: =IFERROR(__xludf.DUMMYFUNCTION("""COMPUTED_VALUE"""),"T") -> T | D6: =IFERROR(__xludf.DUMMYFUNCTION("""COMPUTED_VALUE"""),"表示") -> 表示 | E6: =IFERROR(__xludf.DUMMYFUNCTION("""COMPUTED_VALUE"""),21) -> 21 | F6: =IFERROR(__xludf.DUMMYFUNCTION("""COMPUTED_VALUE"""),"• 『呪術廻戦』：伏黒恵 • 『BANANA FISH』：アッシュ・リンクス • 『ブルーロック』：御影玲王 • 『WIND BREAKER』：桜遥 • 『フルーツバスケット』：草摩夾 • 『マクロスΔ』：ハヤテ・インメルマン • 『りゅうおうのおしごと！』：九頭竜八一") -> • 『呪術廻戦』：伏黒恵 • 『BANANA FISH』：アッシュ・リンクス • 『ブルーロック』：御影玲王 • 『WIND BREAKER』：桜遥 • 『フルーツバスケット』：草摩夾 • 『マクロスΔ』：ハヤテ・インメルマン • 『りゅうおうのおしごと！』：九頭竜八一
A7: =IFERROR(__xludf.DUMMYFUNCTION("""COMPUTED_VALUE"""),"va_033") -> va_033 | B7: =IFERROR(__xludf.DUMMYFUNCTION("""COMPUTED_VALUE"""),"梅原裕一郎") -> 梅原裕一郎 | C7: =IFERROR(__xludf.DUMMYFUNCTION("""COMPUTED_VALUE"""),"T") -> T | D7: =IFERROR(__xludf.DUMMYFUNCTION("""COMPUTED_VALUE"""),"表示") -> 表示 | E7: =IFERROR(__xludf.DUMMYFUNCTION("""COMPUTED_VALUE"""),21) -> 21 | F7: =IFERROR(__xludf.DUMMYFUNCTION("""COMPUTED_VALUE"""),"• 『ゴブリンスレイヤー』：ゴブリンスレイヤー • 『美男高校地球防衛部LOVE!』：由布院煙 • 『あんさんぶるスターズ！』：蓮巳敬人 • 『アイドルマスター SideM』：鷹城恭二 • 『魔王学院の不適合者』：アノス・ヴォルディゴード • 『WIND BREAKER』：十亀条 • 『ディズニー ツイステッドワンダーランド』：レオナ・キングスカラー") -> • 『ゴブリンスレイヤー』：ゴブリンスレイヤー • 『美男高校地球防衛部LOVE!』：由布院煙 • 『あんさんぶるスターズ！』：蓮巳敬人 • 『アイドルマスター SideM』：鷹城恭二 • 『魔王学院の不適合者』：アノス・ヴォルディゴード • 『WIND BREAKER』：十亀条 • 『ディズニー ツイステッドワンダーランド』：レオナ・キングスカラー
A8: =IFERROR(__xludf.DUMMYFUNCTION("""COMPUTED_VALUE"""),"va_042") -> va_042 | B8: =IFERROR(__xludf.DUMMYFUNCTION("""COMPUTED_VALUE"""),"岡本信彦") -> 岡本信彦 | C8: =IFERROR(__xludf.DUMMYFUNCTION("""COMPUTED_VALUE"""),"T") -> T | D8: =IFERROR(__xludf.DUMMYFUNCTION("""COMPUTED_VALUE"""),"表示") -> 表示 | E8: =IFERROR(__xludf.DUMMYFUNCTION("""COMPUTED_VALUE"""),21) -> 21 | F8: =IFERROR(__xludf.DUMMYFUNCTION("""COMPUTED_VALUE"""),"• 『僕のヒーローアカデミア』：爆豪勝己 • 『青の祓魔師』：奥村燐 • 『とある魔術の禁書目録』：一方通行（アクセラレータ） • 『ハイキュー!!』：西谷夕 • 『暗殺教室』：赤羽業 • 『葬送のフリーレン』：ヒンメル • 『鬼滅の刃』：不死川玄弥") -> • 『僕のヒーローアカデミア』：爆豪勝己 • 『青の祓魔師』：奥村燐 • 『とある魔術の禁書目録』：一方通行（アクセラレータ） • 『ハイキュー!!』：西谷夕 • 『暗殺教室』：赤羽業 • 『葬送のフリーレン』：ヒンメル • 『鬼滅の刃』：不死川玄弥
A9: =IFERROR(__xludf.DUMMYFUNCTION("""COMPUTED_VALUE"""),"va_075") -> va_075 | B9: =IFERROR(__xludf.DUMMYFUNCTION("""COMPUTED_VALUE"""),"小林裕介") -> 小林裕介 | C9: =IFERROR(__xludf.DUMMYFUNCTION("""COMPUTED_VALUE"""),"T") -> T | D9: =IFERROR(__xludf.DUMMYFUNCTION("""COMPUTED_VALUE"""),"表示") -> 表示 | E9: =IFERROR(__xludf.DUMMYFUNCTION("""COMPUTED_VALUE"""),21) -> 21 | F9: =IFERROR(__xludf.DUMMYFUNCTION("""COMPUTED_VALUE"""),"• 『Re:ゼロから始める異世界生活』：ナツキ・スバル • 『Dr.STONE』：石神千空 • 『炎炎ノ消防隊』：アーサー・ボイル • 『アルスラーン戦記』：アルスラーン • 『ファイアーエムブレム 風花雪月』：ベレト • 『Paradox Live』：矢戸乃上珂波汰") -> • 『Re:ゼロから始める異世界生活』：ナツキ・スバル • 『Dr.STONE』：石神千空 • 『炎炎ノ消防隊』：アーサー・ボイル • 『アルスラーン戦記』：アルスラーン • 『ファイアーエムブレム 風花雪月』：ベレト • 『Paradox Live』：矢戸乃上珂波汰
A10: =IFERROR(__xludf.DUMMYFUNCTION("""COMPUTED_VALUE"""),"va_131") -> va_131 | B10: =IFERROR(__xludf.DUMMYFUNCTION("""COMPUTED_VALUE"""),"豊永利行") -> 豊永利行 | C10: =IFERROR(__xludf.DUMMYFUNCTION("""COMPUTED_VALUE"""),"T") -> T | D10: =IFERROR(__xludf.DUMMYFUNCTION("""COMPUTED_VALUE"""),"表示") -> 表示 | E10: =IFERROR(__xludf.DUMMYFUNCTION("""COMPUTED_VALUE"""),21) -> 21 | F10: =IFERROR(__xludf.DUMMYFUNCTION("""COMPUTED_VALUE"""),"• 『デュラララ!!』：竜ヶ峰帝人 • 『ユーリ!!! on ICE』：勝生勇利 • 『Free!』：椎名旭 • 『文豪ストレイドッグス』：谷崎潤一郎 • 『ハイキュー!!』：白布賢二郎 • 『ドラゴンクエスト ダイの大冒険』：ポップ • 『東京喰種トーキョーグール』：永近英良") -> • 『デュラララ!!』：竜ヶ峰帝人 • 『ユーリ!!! on ICE』：勝生勇利 • 『Free!』：椎名旭 • 『文豪ストレイドッグス』：谷崎潤一郎 • 『ハイキュー!!』：白布賢二郎 • 『ドラゴンクエスト ダイの大冒険』：ポップ • 『東京喰種トーキョーグール』：永近英良
A11: =IFERROR(__xludf.DUMMYFUNCTION("""COMPUTED_VALUE"""),"va_188") -> va_188 | B11: =IFERROR(__xludf.DUMMYFUNCTION("""COMPUTED_VALUE"""),"八代拓") -> 八代拓 | C11: =IFERROR(__xludf.DUMMYFUNCTION("""COMPUTED_VALUE"""),"T") -> T | D11: =IFERROR(__xludf.DUMMYFUNCTION("""COMPUTED_VALUE"""),"表示") -> 表示 | E11: =IFERROR(__xludf.DUMMYFUNCTION("""COMPUTED_VALUE"""),21) -> 21 | F11: =IFERROR(__xludf.DUMMYFUNCTION("""COMPUTED_VALUE"""),"• 『KING OF PRISM』：十王院カケル • 『タイガーマスクW』：東ナオト／タイガーマスク • 『炎炎ノ消防隊』：ヴァルカン・ジョゼフ • 『アイドルマスター SideM』：柏木翼 • 『ドメスティックな彼女』：藤井夏生 • 『るろうに剣心 －明治剣客浪漫譚－』：相楽左之助 • 『ポケットモンスター』（2023年版）：フリード • 『千銃士』：ブラウン・ベス") -> • 『KING OF PRISM』：十王院カケル • 『タイガーマスクW』：東ナオト／タイガーマスク • 『炎炎ノ消防隊』：ヴァルカン・ジョゼフ • 『アイドルマスター SideM』：柏木翼 • 『ドメスティックな彼女』：藤井夏生 • 『るろうに剣心 －明治剣客浪漫譚－』：相楽左之助 • 『ポケットモンスター』（2023年版）：フリード • 『千銃士』：ブラウン・ベス
A12: =IFERROR(__xludf.DUMMYFUNCTION("""COMPUTED_VALUE"""),"va_035") -> va_035 | B12: =IFERROR(__xludf.DUMMYFUNCTION("""COMPUTED_VALUE"""),"江口拓也") -> 江口拓也 | C12: =IFERROR(__xludf.DUMMYFUNCTION("""COMPUTED_VALUE"""),"T") -> T | D12: =IFERROR(__xludf.DUMMYFUNCTION("""COMPUTED_VALUE"""),"表示") -> 表示 | E12: =IFERROR(__xludf.DUMMYFUNCTION("""COMPUTED_VALUE"""),20) -> 20 | F12: =IFERROR(__xludf.DUMMYFUNCTION("""COMPUTED_VALUE"""),"• 『SPY×FAMILY』：ロイド・フォージャー • 『やはり俺の青春ラブコメはまちがっている。』：比企谷八幡 • 『アイドリッシュセブン』：六弥ナギ • 『東京リベンジャーズ』：半間修二 • 『転生したらスライムだった件』：ソウエイ • 『マッシュル-MASHLE-』：ドット・バレット • 『あんさんぶるスターズ！』：日々樹渉") -> • 『SPY×FAMILY』：ロイド・フォージャー • 『やはり俺の青春ラブコメはまちがっている。』：比企谷八幡 • 『アイドリッシュセブン』：六弥ナギ • 『東京リベンジャーズ』：半間修二 • 『転生したらスライムだった件』：ソウエイ • 『マッシュル-MASHLE-』：ドット・バレット • 『あんさんぶるスターズ！』：日々樹渉
A13: =IFERROR(__xludf.DUMMYFUNCTION("""COMPUTED_VALUE"""),"va_046") -> va_046 | B13: =IFERROR(__xludf.DUMMYFUNCTION("""COMPUTED_VALUE"""),"小野友樹") -> 小野友樹 | C13: =IFERROR(__xludf.DUMMYFUNCTION("""COMPUTED_VALUE"""),"T") -> T | D13: =IFERROR(__xludf.DUMMYFUNCTION("""COMPUTED_VALUE"""),"表示") -> 表示 | E13: =IFERROR(__xludf.DUMMYFUNCTION("""COMPUTED_VALUE"""),20) -> 20 | F13: =IFERROR(__xludf.DUMMYFUNCTION("""COMPUTED_VALUE"""),"• 『黒子のバスケ』：火神大我 • 『ジョジョの奇妙な冒険 ダイヤモンドは砕けない』：東方仗助 • 『あんさんぶるスターズ！』：大神晃牙 • 『抱かれたい男1位に脅されています。』：東谷准太 • 『ブルーロック』：國神錬介") -> • 『黒子のバスケ』：火神大我 • 『ジョジョの奇妙な冒険 ダイヤモンドは砕けない』：東方仗助 • 『あんさんぶるスターズ！』：大神晃牙 • 『抱かれたい男1位に脅されています。』：東谷准太 • 『ブルーロック』：國神錬介
A14: =IFERROR(__xludf.DUMMYFUNCTION("""COMPUTED_VALUE"""),"va_090") -> va_090 | B14: =IFERROR(__xludf.DUMMYFUNCTION("""COMPUTED_VALUE"""),"佐藤拓也") -> 佐藤拓也 | C14: =IFERROR(__xludf.DUMMYFUNCTION("""COMPUTED_VALUE"""),"T") -> T | D14: =IFERROR(__xludf.DUMMYFUNCTION("""COMPUTED_VALUE"""),"表示") -> 表示 | E14: =IFERROR(__xludf.DUMMYFUNCTION("""COMPUTED_VALUE"""),20) -> 20 | F14: =IFERROR(__xludf.DUMMYFUNCTION("""COMPUTED_VALUE"""),"• 『アイドリッシュセブン』：十龍之介 • 『カードファイト!! ヴァンガード』：櫂トシキ • 『ジョジョの奇妙な冒険』：シーザー・アントニオ・ツェペリ • 『憂国のモリアーティ』：アルバート・ジェームズ・モリアーティ • 『刀剣乱舞』：燭台切光忠 • 『魔入りました！入間くん』：サブノック・サブロ • 『キャプテン翼』：日向小次郎") -> • 『アイドリッシュセブン』：十龍之介 • 『カードファイト!! ヴァンガード』：櫂トシキ • 『ジョジョの奇妙な冒険』：シーザー・アントニオ・ツェペリ • 『憂国のモリアーティ』：アルバート・ジェームズ・モリアーティ • 『刀剣乱舞』：燭台切光忠 • 『魔入りました！入間くん』：サブノック・サブロ • 『キャプテン翼』：日向小次郎
A15: =IFERROR(__xludf.DUMMYFUNCTION("""COMPUTED_VALUE"""),"va_117") -> va_117 | B15: =IFERROR(__xludf.DUMMYFUNCTION("""COMPUTED_VALUE"""),"田丸篤志") -> 田丸篤志 | C15: =IFERROR(__xludf.DUMMYFUNCTION("""COMPUTED_VALUE"""),"T") -> T | D15: =IFERROR(__xludf.DUMMYFUNCTION("""COMPUTED_VALUE"""),"表示") -> 表示 | E15: =IFERROR(__xludf.DUMMYFUNCTION("""COMPUTED_VALUE"""),20) -> 20 | F15: =IFERROR(__xludf.DUMMYFUNCTION("""COMPUTED_VALUE"""),"• 『A3!』：月岡紬 • 『ディズニー ツイステッドワンダーランド』：アズール・アーシェングロット • 『刀剣乱舞』：一期一振 • 『七つの魔剣が支配する』：オリバー＝ホーン • 『魔法科高校の劣等生』：吉田幹比古 • 『ハイキュー!!』：国見英 • 『月がきれい』：比良拓海") -> • 『A3!』：月岡紬 • 『ディズニー ツイステッドワンダーランド』：アズール・アーシェングロット • 『刀剣乱舞』：一期一振 • 『七つの魔剣が支配する』：オリバー＝ホーン • 『魔法科高校の劣等生』：吉田幹比古 • 『ハイキュー!!』：国見英 • 『月がきれい』：比良拓海
A16: =IFERROR(__xludf.DUMMYFUNCTION("""COMPUTED_VALUE"""),"va_150") -> va_150 | B16: =IFERROR(__xludf.DUMMYFUNCTION("""COMPUTED_VALUE"""),"花江夏樹") -> 花江夏樹 | C16: =IFERROR(__xludf.DUMMYFUNCTION("""COMPUTED_VALUE"""),"T") -> T | D16: =IFERROR(__xludf.DUMMYFUNCTION("""COMPUTED_VALUE"""),"表示") -> 表示 | E16: =IFERROR(__xludf.DUMMYFUNCTION("""COMPUTED_VALUE"""),20) -> 20 | F16: =IFERROR(__xludf.DUMMYFUNCTION("""COMPUTED_VALUE"""),"• 『鬼滅の刃』： 竈門炭治郎 • 『東京喰種トーキョーグール』： 金木研／佐々木琲世 • 『四月は君の嘘』： 有馬公生 • 『ヴァニタスの手記』： ヴァニタス • 『サマータイムレンダ』： 網代慎平 • 『ALDNOAH.ZERO』： 界塚伊奈帆 • 『ダイヤのA』： 小湊春市") -> • 『鬼滅の刃』： 竈門炭治郎 • 『東京喰種トーキョーグール』： 金木研／佐々木琲世 • 『四月は君の嘘』： 有馬公生 • 『ヴァニタスの手記』： ヴァニタス • 『サマータイムレンダ』： 網代慎平 • 『ALDNOAH.ZERO』： 界塚伊奈帆 • 『ダイヤのA』： 小湊春市
A17: =IFERROR(__xludf.DUMMYFUNCTION("""COMPUTED_VALUE"""),"va_066") -> va_066 | B17: =IFERROR(__xludf.DUMMYFUNCTION("""COMPUTED_VALUE"""),"木村良平") -> 木村良平 | C17: =IFERROR(__xludf.DUMMYFUNCTION("""COMPUTED_VALUE"""),"T") -> T | D17: =IFERROR(__xludf.DUMMYFUNCTION("""COMPUTED_VALUE"""),"表示") -> 表示 | E17: =IFERROR(__xludf.DUMMYFUNCTION("""COMPUTED_VALUE"""),19) -> 19 | F17: =IFERROR(__xludf.DUMMYFUNCTION("""COMPUTED_VALUE"""),"• 『黒子のバスケ』：黄瀬涼太 • 『ハイキュー!!』：木兎光太郎 • 『魔道祖師』：魏無羨 • 『原神』：タルタリヤ • 『DIABOLIK LOVERS』：無神コウ • 『ツキウタ。』：霜月隼 • 『東のエデン』：滝沢朗") -> • 『黒子のバスケ』：黄瀬涼太 • 『ハイキュー!!』：木兎光太郎 • 『魔道祖師』：魏無羨 • 『原神』：タルタリヤ • 『DIABOLIK LOVERS』：無神コウ • 『ツキウタ。』：霜月隼 • 『東のエデン』：滝沢朗
A18: =IFERROR(__xludf.DUMMYFUNCTION("""COMPUTED_VALUE"""),"va_094") -> va_094 | B18: =IFERROR(__xludf.DUMMYFUNCTION("""COMPUTED_VALUE"""),"島﨑信長") -> 島﨑信長 | C18: =IFERROR(__xludf.DUMMYFUNCTION("""COMPUTED_VALUE"""),"T") -> T | D18: =IFERROR(__xludf.DUMMYFUNCTION("""COMPUTED_VALUE"""),"表示") -> 表示 | E18: =IFERROR(__xludf.DUMMYFUNCTION("""COMPUTED_VALUE"""),19) -> 19 | F18: =IFERROR(__xludf.DUMMYFUNCTION("""COMPUTED_VALUE"""),"• 『Free!』：七瀬遙 • 『ブルーロック』：凪誠士郎 • 『フルーツバスケット』：草摩由希 • 『呪術廻戦』：真人 • 『ダイヤのA』：降谷暁 • 『デート・ア・ライブ』：五河士道 • 『ブラッククローバー』：ユノ • 『WIND BREAKER』：蘇枋隼飛") -> • 『Free!』：七瀬遙 • 『ブルーロック』：凪誠士郎 • 『フルーツバスケット』：草摩由希 • 『呪術廻戦』：真人 • 『ダイヤのA』：降谷暁 • 『デート・ア・ライブ』：五河士道 • 『ブラッククローバー』：ユノ • 『WIND BREAKER』：蘇枋隼飛
A19: =IFERROR(__xludf.DUMMYFUNCTION("""COMPUTED_VALUE"""),"va_112") -> va_112 | B19: =IFERROR(__xludf.DUMMYFUNCTION("""COMPUTED_VALUE"""),"武内駿輔") -> 武内駿輔 | C19: =IFERROR(__xludf.DUMMYFUNCTION("""COMPUTED_VALUE"""),"T") -> T | D19: =IFERROR(__xludf.DUMMYFUNCTION("""COMPUTED_VALUE"""),"表示") -> 表示 | E19: =IFERROR(__xludf.DUMMYFUNCTION("""COMPUTED_VALUE"""),19) -> 19 | F19: =IFERROR(__xludf.DUMMYFUNCTION("""COMPUTED_VALUE"""),"• 『遊☆戯☆王VRAINS』：鴻上了見／リボルバー • 『THE FIRST SLAM DUNK』：沢北栄治 • 『KING OF PRISM』：大和アレクサンダー • 『アイドルマスター シンデレラガールズ』：プロデューサー • 『アナと雪の女王2』：オラフ • 『機動戦士ガンダム ククルス・ドアンの島』：ククルス・ドアン") -> • 『遊☆戯☆王VRAINS』：鴻上了見／リボルバー • 『THE FIRST SLAM DUNK』：沢北栄治 • 『KING OF PRISM』：大和アレクサンダー • 『アイドルマスター シンデレラガールズ』：プロデューサー • 『アナと雪の女王2』：オラフ • 『機動戦士ガンダム ククルス・ドアンの島』：ククルス・ドアン
A20: =IFERROR(__xludf.DUMMYFUNCTION("""COMPUTED_VALUE"""),"va_102") -> va_102 | B20: =IFERROR(__xludf.DUMMYFUNCTION("""COMPUTED_VALUE"""),"諏訪部順一") -> 諏訪部順一 | C20: =IFERROR(__xludf.DUMMYFUNCTION("""COMPUTED_VALUE"""),"T") -> T | D20: =IFERROR(__xludf.DUMMYFUNCTION("""COMPUTED_VALUE"""),"表示") -> 表示 | E20: =IFERROR(__xludf.DUMMYFUNCTION("""COMPUTED_VALUE"""),18) -> 18 | F20: =IFERROR(__xludf.DUMMYFUNCTION("""COMPUTED_VALUE"""),"• 『テニスの王子様』：跡部景吾 • 『Fate/stay night』：アーチャー • 『うたの☆プリンスさまっ♪』：神宮寺レン • 『ユーリ!!! on ICE』：ヴィクトル・ニキフォロフ • 『呪術廻戦』：両面宿儺 • 『黒執事』：アンダーテイカー • 『BLEACH』：グリムジョー・ジャガージャック • 『僕のヒーローアカデミア』：相澤消太") -> • 『テニスの王子様』：跡部景吾 • 『Fate/stay night』：アーチャー • 『うたの☆プリンスさまっ♪』：神宮寺レン • 『ユーリ!!! on ICE』：ヴィクトル・ニキフォロフ • 『呪術廻戦』：両面宿儺 • 『黒執事』：アンダーテイカー • 『BLEACH』：グリムジョー・ジャガージャック • 『僕のヒーローアカデミア』：相澤消太
A21: =IFERROR(__xludf.DUMMYFUNCTION("""COMPUTED_VALUE"""),"va_114") -> va_114 | B21: =IFERROR(__xludf.DUMMYFUNCTION("""COMPUTED_VALUE"""),"立花慎之介") -> 立花慎之介 | C21: =IFERROR(__xludf.DUMMYFUNCTION("""COMPUTED_VALUE"""),"T") -> T | D21: =IFERROR(__xludf.DUMMYFUNCTION("""COMPUTED_VALUE"""),"表示") -> 表示 | E21: =IFERROR(__xludf.DUMMYFUNCTION("""COMPUTED_VALUE"""),18) -> 18 | F21: =IFERROR(__xludf.DUMMYFUNCTION("""COMPUTED_VALUE"""),"• 『アイドリッシュセブン』：千（ユキ） • 『神様はじめました』：巴衛 • 『ハイキュー!!』：夜久衛輔 • 『世界一初恋』：吉野千秋 • 『セキレイ』：佐橋皆人 • 『恋と深空』：ホムラ") -> • 『アイドリッシュセブン』：千（ユキ） • 『神様はじめました』：巴衛 • 『ハイキュー!!』：夜久衛輔 • 『世界一初恋』：吉野千秋 • 『セキレイ』：佐橋皆人 • 『恋と深空』：ホムラ
A22: =IFERROR(__xludf.DUMMYFUNCTION("""COMPUTED_VALUE"""),"va_132") -> va_132 | B22: =IFERROR(__xludf.DUMMYFUNCTION("""COMPUTED_VALUE"""),"鳥海浩輔") -> 鳥海浩輔 | C22: =IFERROR(__xludf.DUMMYFUNCTION("""COMPUTED_VALUE"""),"T") -> T | D22: =IFERROR(__xludf.DUMMYFUNCTION("""COMPUTED_VALUE"""),"表示") -> 表示 | E22: =IFERROR(__xludf.DUMMYFUNCTION("""COMPUTED_VALUE"""),18) -> 18 | F22: =IFERROR(__xludf.DUMMYFUNCTION("""COMPUTED_VALUE"""),"• 『うたの☆プリンスさまっ♪』：愛島セシル • 『薄桜鬼』：斎藤一 • 『刀剣乱舞』：三日月宗近 • 『弱虫ペダル』：今泉俊輔 • 『あんさんぶるスターズ！！』：三毛縞斑 • 『DIABOLIK LOVERS』：逆巻シュウ • 『ハイキュー!!』：佐久早聖臣 • 『ジョジョの奇妙な冒険 黄金の風』：グイード・ミスタ • 『NARUTO』：犬塚キバ • 『Thunderbolt Fantasy 東離劍遊紀』：凜雪鴉") -> • 『うたの☆プリンスさまっ♪』：愛島セシル • 『薄桜鬼』：斎藤一 • 『刀剣乱舞』：三日月宗近 • 『弱虫ペダル』：今泉俊輔 • 『あんさんぶるスターズ！！』：三毛縞斑 • 『DIABOLIK LOVERS』：逆巻シュウ • 『ハイキュー!!』：佐久早聖臣 • 『ジョジョの奇妙な冒険 黄金の風』：グイード・ミスタ • 『NARUTO』：犬塚キバ • 『Thunderbolt Fantasy 東離劍遊紀』：凜雪鴉
A23: =IFERROR(__xludf.DUMMYFUNCTION("""COMPUTED_VALUE"""),"va_172") -> va_172 | B23: =IFERROR(__xludf.DUMMYFUNCTION("""COMPUTED_VALUE"""),"増田俊樹") -> 増田俊樹 | C23: =IFERROR(__xludf.DUMMYFUNCTION("""COMPUTED_VALUE"""),"T") -> T | D23: =IFERROR(__xludf.DUMMYFUNCTION("""COMPUTED_VALUE"""),"表示") -> 表示 | E23: =IFERROR(__xludf.DUMMYFUNCTION("""COMPUTED_VALUE"""),18) -> 18 | F23: =IFERROR(__xludf.DUMMYFUNCTION("""COMPUTED_VALUE"""),"• 『僕のヒーローアカデミア』：切島鋭児郎 • 『アイドリッシュセブン』：和泉一織 • 『あんさんぶるスターズ！！』：朔間零 • 『刀剣乱舞』：加州清光 • 『遊☆戯☆王ZEXAL』：神代凌牙 • 『進撃の巨人』：ポルコ・ガリアード • 『ハイキュー!!』：縁下力") -> • 『僕のヒーローアカデミア』：切島鋭児郎 • 『アイドリッシュセブン』：和泉一織 • 『あんさんぶるスターズ！！』：朔間零 • 『刀剣乱舞』：加州清光 • 『遊☆戯☆王ZEXAL』：神代凌牙 • 『進撃の巨人』：ポルコ・ガリアード • 『ハイキュー!!』：縁下力
A24: =IFERROR(__xludf.DUMMYFUNCTION("""COMPUTED_VALUE"""),"va_009") -> va_009 | B24: =IFERROR(__xludf.DUMMYFUNCTION("""COMPUTED_VALUE"""),"蒼井翔太") -> 蒼井翔太 | C24: =IFERROR(__xludf.DUMMYFUNCTION("""COMPUTED_VALUE"""),"T") -> T | D24: =IFERROR(__xludf.DUMMYFUNCTION("""COMPUTED_VALUE"""),"表示") -> 表示 | E24: =IFERROR(__xludf.DUMMYFUNCTION("""COMPUTED_VALUE"""),17) -> 17 | F24: =IFERROR(__xludf.DUMMYFUNCTION("""COMPUTED_VALUE"""),"• 『うたの☆プリンスさまっ♪』：美風藍 • 『KING OF PRISM』：如月ルヰ • 『乙女ゲームの破滅フラグしかない悪役令嬢に転生してしまった…』：ジオルド・スティアート • 『ツキウタ。』：水無月涙 • 『ヴィジュアルプリズン』：ハイド・ジャイエ") -> • 『うたの☆プリンスさまっ♪』：美風藍 • 『KING OF PRISM』：如月ルヰ • 『乙女ゲームの破滅フラグしかない悪役令嬢に転生してしまった…』：ジオルド・スティアート • 『ツキウタ。』：水無月涙 • 『ヴィジュアルプリズン』：ハイド・ジャイエ
A25: =IFERROR(__xludf.DUMMYFUNCTION("""COMPUTED_VALUE"""),"va_051") -> va_051 | B25: =IFERROR(__xludf.DUMMYFUNCTION("""COMPUTED_VALUE"""),"梶裕貴") -> 梶裕貴 | C25: =IFERROR(__xludf.DUMMYFUNCTION("""COMPUTED_VALUE"""),"T") -> T | D25: =IFERROR(__xludf.DUMMYFUNCTION("""COMPUTED_VALUE"""),"表示") -> 表示 | E25: =IFERROR(__xludf.DUMMYFUNCTION("""COMPUTED_VALUE"""),17) -> 17 | F25: =IFERROR(__xludf.DUMMYFUNCTION("""COMPUTED_VALUE"""),"• 『進撃の巨人』：エレン・イェーガー • 『僕のヒーローアカデミア』：轟焦凍 • 『七つの大罪』：メリオダス • 『マギ』：アリババ・サルージャ • 『ハイキュー!!』：孤爪研磨 • 『黒執事』：フィニアン") -> • 『進撃の巨人』：エレン・イェーガー • 『僕のヒーローアカデミア』：轟焦凍 • 『七つの大罪』：メリオダス • 『マギ』：アリババ・サルージャ • 『ハイキュー!!』：孤爪研磨 • 『黒執事』：フィニアン
A26: =IFERROR(__xludf.DUMMYFUNCTION("""COMPUTED_VALUE"""),"va_141") -> va_141 | B26: =IFERROR(__xludf.DUMMYFUNCTION("""COMPUTED_VALUE"""),"西山宏太朗") -> 西山宏太朗 | C26: =IFERROR(__xludf.DUMMYFUNCTION("""COMPUTED_VALUE"""),"T") -> T | D26: =IFERROR(__xludf.DUMMYFUNCTION("""COMPUTED_VALUE"""),"表示") -> 表示 | E26: =IFERROR(__xludf.DUMMYFUNCTION("""COMPUTED_VALUE"""),17) -> 17 | F26: =IFERROR(__xludf.DUMMYFUNCTION("""COMPUTED_VALUE"""),"• 『アイドリッシュセブン』：棗巳波 • 『あんさんぶるスターズ！』：深海奏汰 • 『学園ベビーシッターズ』：鹿島竜一 • 『A3!』：皆木綴 • 『B-PROJECT』：寺光唯月 • 『美男高校地球防衛部LOVE！』：鬼怒川熱史 • 『スタンドマイヒーローズ』：都築京介") -> • 『アイドリッシュセブン』：棗巳波 • 『あんさんぶるスターズ！』：深海奏汰 • 『学園ベビーシッターズ』：鹿島竜一 • 『A3!』：皆木綴 • 『B-PROJECT』：寺光唯月 • 『美男高校地球防衛部LOVE！』：鬼怒川熱史 • 『スタンドマイヒーローズ』：都築京介
A27: =IFERROR(__xludf.DUMMYFUNCTION("""COMPUTED_VALUE"""),"va_124") -> va_124 | B27: =IFERROR(__xludf.DUMMYFUNCTION("""COMPUTED_VALUE"""),"寺島惇太") -> 寺島惇太 | C27: =IFERROR(__xludf.DUMMYFUNCTION("""COMPUTED_VALUE"""),"T") -> T | D27: =IFERROR(__xludf.DUMMYFUNCTION("""COMPUTED_VALUE"""),"表示") -> 表示 | E27: =IFERROR(__xludf.DUMMYFUNCTION("""COMPUTED_VALUE"""),16) -> 16 | F27: =IFERROR(__xludf.DUMMYFUNCTION("""COMPUTED_VALUE"""),"• 『KING OF PRISM』：一条シン • 『アイドルマスター SideM』：大河タケル • 『A3!』：御影密 • 『ツキプロ』：藤村衛 • 『Paradox Live』：闇堂四季 • 『この音とまれ！』：桐生桜介") -> • 『KING OF PRISM』：一条シン • 『アイドルマスター SideM』：大河タケル • 『A3!』：御影密 • 『ツキプロ』：藤村衛 • 『Paradox Live』：闇堂四季 • 『この音とまれ！』：桐生桜介
A28: =IFERROR(__xludf.DUMMYFUNCTION("""COMPUTED_VALUE"""),"va_013") -> va_013 | B28: =IFERROR(__xludf.DUMMYFUNCTION("""COMPUTED_VALUE"""),"石川界人") -> 石川界人 | C28: =IFERROR(__xludf.DUMMYFUNCTION("""COMPUTED_VALUE"""),"T") -> T | D28: =IFERROR(__xludf.DUMMYFUNCTION("""COMPUTED_VALUE"""),"表示") -> 表示 | E28: =IFERROR(__xludf.DUMMYFUNCTION("""COMPUTED_VALUE"""),15) -> 15 | F28: =IFERROR(__xludf.DUMMYFUNCTION("""COMPUTED_VALUE"""),"• 『ハイキュー!!』：影山飛雄 • 『ワンパンマン』：ジェノス • 『僕のヒーローアカデミア』：飯田天哉 • 『盾の勇者の成り上がり』：岩谷尚文 • 『青春ブタ野郎シリーズ』：梓川咲太 • 『わたしの幸せな結婚』：久堂清霞") -> • 『ハイキュー!!』：影山飛雄 • 『ワンパンマン』：ジェノス • 『僕のヒーローアカデミア』：飯田天哉 • 『盾の勇者の成り上がり』：岩谷尚文 • 『青春ブタ野郎シリーズ』：梓川咲太 • 『わたしの幸せな結婚』：久堂清霞
A29: =IFERROR(__xludf.DUMMYFUNCTION("""COMPUTED_VALUE"""),"va_096") -> va_096 | B29: =IFERROR(__xludf.DUMMYFUNCTION("""COMPUTED_VALUE"""),"白井悠介") -> 白井悠介 | C29: =IFERROR(__xludf.DUMMYFUNCTION("""COMPUTED_VALUE"""),"T") -> T | D29: =IFERROR(__xludf.DUMMYFUNCTION("""COMPUTED_VALUE"""),"表示") -> 表示 | E29: =IFERROR(__xludf.DUMMYFUNCTION("""COMPUTED_VALUE"""),15) -> 15 | F29: =IFERROR(__xludf.DUMMYFUNCTION("""COMPUTED_VALUE"""),"• 『ヒプノシスマイク』：飴村乱数 • 『アイドリッシュセブン』：二階堂大和 • 『佐々木と宮野』：佐々木秀鳴 • 『美男高校地球防衛部LOVE!』：鳴子硫黄 • 『戦闘員、派遣します!』：戦闘員六号 • 『誰ソ彼ホテル』：大外聖生") -> • 『ヒプノシスマイク』：飴村乱数 • 『アイドリッシュセブン』：二階堂大和 • 『佐々木と宮野』：佐々木秀鳴 • 『美男高校地球防衛部LOVE!』：鳴子硫黄 • 『戦闘員、派遣します!』：戦闘員六号 • 『誰ソ彼ホテル』：大外聖生
A30: =IFERROR(__xludf.DUMMYFUNCTION("""COMPUTED_VALUE"""),"va_147") -> va_147 | B30: =IFERROR(__xludf.DUMMYFUNCTION("""COMPUTED_VALUE"""),"畠中祐") -> 畠中祐 | C30: =IFERROR(__xludf.DUMMYFUNCTION("""COMPUTED_VALUE"""),"T") -> T | D30: =IFERROR(__xludf.DUMMYFUNCTION("""COMPUTED_VALUE"""),"表示") -> 表示 | E30: =IFERROR(__xludf.DUMMYFUNCTION("""COMPUTED_VALUE"""),15) -> 15 | F30: =IFERROR(__xludf.DUMMYFUNCTION("""COMPUTED_VALUE"""),"• 『遊☆戯☆王ZEXAL』：九十九遊馬 • 『僕のヒーローアカデミア』：上鳴電気 • 『KING OF PRISM』：香賀美タイガ • 『東京リベンジャーズ』：柴八戒 • 『SK∞ エスケーエイト』：喜屋武暦 • 『甲鉄城のカバネリ』：生駒 • 『うしおととら』：蒼月潮 • 『ウルトラマンZ』：ナツカワ・ハルキ • 『ザ・スーパーマリオブラザーズ・ムービー』：ルイージ") -> • 『遊☆戯☆王ZEXAL』：九十九遊馬 • 『僕のヒーローアカデミア』：上鳴電気 • 『KING OF PRISM』：香賀美タイガ • 『東京リベンジャーズ』：柴八戒 • 『SK∞ エスケーエイト』：喜屋武暦 • 『甲鉄城のカバネリ』：生駒 • 『うしおととら』：蒼月潮 • 『ウルトラマンZ』：ナツカワ・ハルキ • 『ザ・スーパーマリオブラザーズ・ムービー』：ルイージ
A31: =IFERROR(__xludf.DUMMYFUNCTION("""COMPUTED_VALUE"""),"va_157") -> va_157 | B31: =IFERROR(__xludf.DUMMYFUNCTION("""COMPUTED_VALUE"""),"平川大輔") -> 平川大輔 | C31: =IFERROR(__xludf.DUMMYFUNCTION("""COMPUTED_VALUE"""),"T") -> T | D31: =IFERROR(__xludf.DUMMYFUNCTION("""COMPUTED_VALUE"""),"表示") -> 表示 | E31: =IFERROR(__xludf.DUMMYFUNCTION("""COMPUTED_VALUE"""),15) -> 15 | F31: =IFERROR(__xludf.DUMMYFUNCTION("""COMPUTED_VALUE"""),"• 『ジョジョの奇妙な冒険 スターダストクルセイダース』： 花京院典明 • 『Free!』： 竜ヶ崎怜 • 『DIABOLIK LOVERS』： 逆巻ライト • 『イタズラなKiss』： 入江直樹 • 『School Days』： 伊藤誠 • 『巌窟王』： フランツ・デピネー • 『鬼滅の刃』： 魘夢") -> • 『ジョジョの奇妙な冒険 スターダストクルセイダース』： 花京院典明 • 『Free!』： 竜ヶ崎怜 • 『DIABOLIK LOVERS』： 逆巻ライト • 『イタズラなKiss』： 入江直樹 • 『School Days』： 伊藤誠 • 『巌窟王』： フランツ・デピネー • 『鬼滅の刃』： 魘夢
A32: =IFERROR(__xludf.DUMMYFUNCTION("""COMPUTED_VALUE"""),"va_183") -> va_183 | B32: =IFERROR(__xludf.DUMMYFUNCTION("""COMPUTED_VALUE"""),"村瀬歩") -> 村瀬歩 | C32: =IFERROR(__xludf.DUMMYFUNCTION("""COMPUTED_VALUE"""),"T") -> T | D32: =IFERROR(__xludf.DUMMYFUNCTION("""COMPUTED_VALUE"""),"表示") -> 表示 | E32: =IFERROR(__xludf.DUMMYFUNCTION("""COMPUTED_VALUE"""),15) -> 15 | F32: =IFERROR(__xludf.DUMMYFUNCTION("""COMPUTED_VALUE"""),"• 『ハイキュー!!』：日向翔陽 • 『魔入りました！入間くん』：鈴木入間 • 『あんさんぶるスターズ！』：姫宮桃李 • 『原神』：ウェンティ • 『アイドルマスター SideM』：姫野かのん • 『ひろがるスカイ！プリキュア』：夕凪ツバサ／キュアウィング • 『王様ランキング』：カゲ") -> • 『ハイキュー!!』：日向翔陽 • 『魔入りました！入間くん』：鈴木入間 • 『あんさんぶるスターズ！』：姫宮桃李 • 『原神』：ウェンティ • 『アイドルマスター SideM』：姫野かのん • 『ひろがるスカイ！プリキュア』：夕凪ツバサ／キュアウィング • 『王様ランキング』：カゲ
A33: =IFERROR(__xludf.DUMMYFUNCTION("""COMPUTED_VALUE"""),"va_200") -> va_200 | B33: =IFERROR(__xludf.DUMMYFUNCTION("""COMPUTED_VALUE"""),"KENN") -> KENN | C33: =IFERROR(__xludf.DUMMYFUNCTION("""COMPUTED_VALUE"""),"T") -> T | D33: =IFERROR(__xludf.DUMMYFUNCTION("""COMPUTED_VALUE"""),"表示") -> 表示 | E33: =IFERROR(__xludf.DUMMYFUNCTION("""COMPUTED_VALUE"""),15) -> 15 | F33: =IFERROR(__xludf.DUMMYFUNCTION("""COMPUTED_VALUE"""),"• 『遊☆戯☆王デュエルモンスターズGX』： 遊城十代 • 『アイドリッシュセブン』： 四葉環 • 『宇宙兄弟』： 南波日々人 • 『境界の彼方』： 神原秋人 • 『サイバーパンク エッジランナーズ』： デイビッド・マルティネス • 『逆転裁判』シリーズ： 王泥喜法介 • 『エア・ギア』： 美鞍葛馬（カズ） • 『アイ★チュウ』： 愛童星夜") -> • 『遊☆戯☆王デュエルモンスターズGX』： 遊城十代 • 『アイドリッシュセブン』： 四葉環 • 『宇宙兄弟』： 南波日々人 • 『境界の彼方』： 神原秋人 • 『サイバーパンク エッジランナーズ』： デイビッド・マルティネス • 『逆転裁判』シリーズ： 王泥喜法介 • 『エア・ギア』： 美鞍葛馬（カズ） • 『アイ★チュウ』： 愛童星夜
A34: =IFERROR(__xludf.DUMMYFUNCTION("""COMPUTED_VALUE"""),"va_019") -> va_019 | B34: =IFERROR(__xludf.DUMMYFUNCTION("""COMPUTED_VALUE"""),"伊東健人") -> 伊東健人 | C34: =IFERROR(__xludf.DUMMYFUNCTION("""COMPUTED_VALUE"""),"T") -> T | D34: =IFERROR(__xludf.DUMMYFUNCTION("""COMPUTED_VALUE"""),"表示") -> 表示 | E34: =IFERROR(__xludf.DUMMYFUNCTION("""COMPUTED_VALUE"""),14) -> 14 | F34: =IFERROR(__xludf.DUMMYFUNCTION("""COMPUTED_VALUE"""),"• 『ヲタクに恋は難しい』：二藤宏嵩 • 『【推しの子】』：ゴロー • 『ヒプノシスマイク』：観音坂独歩 • 『アイドルマスター SideM』：硲道夫 • 『プロジェクトセカイ カラフルステージ！』：青柳冬弥") -> • 『ヲタクに恋は難しい』：二藤宏嵩 • 『【推しの子】』：ゴロー • 『ヒプノシスマイク』：観音坂独歩 • 『アイドルマスター SideM』：硲道夫 • 『プロジェクトセカイ カラフルステージ！』：青柳冬弥
A35: =IFERROR(__xludf.DUMMYFUNCTION("""COMPUTED_VALUE"""),"va_037") -> va_037 | B35: =IFERROR(__xludf.DUMMYFUNCTION("""COMPUTED_VALUE"""),"逢坂良太") -> 逢坂良太 | C35: =IFERROR(__xludf.DUMMYFUNCTION("""COMPUTED_VALUE"""),"T") -> T | D35: =IFERROR(__xludf.DUMMYFUNCTION("""COMPUTED_VALUE"""),"表示") -> 表示 | E35: =IFERROR(__xludf.DUMMYFUNCTION("""COMPUTED_VALUE"""),14) -> 14 | F35: =IFERROR(__xludf.DUMMYFUNCTION("""COMPUTED_VALUE"""),"• 『ダイヤのA』：沢村栄純 • 『はたらく魔王さま！』：真奥貞夫（魔王サタン） • 『ハイキュー!!』：赤葦京治 • 『あんさんぶるスターズ！！』：七種茨 • 『赤髪の白雪姫』：ゼン • 『進撃の巨人』：マルコ・ボット • 『鬼滅の刃』：妓夫太郎") -> • 『ダイヤのA』：沢村栄純 • 『はたらく魔王さま！』：真奥貞夫（魔王サタン） • 『ハイキュー!!』：赤葦京治 • 『あんさんぶるスターズ！！』：七種茨 • 『赤髪の白雪姫』：ゼン • 『進撃の巨人』：マルコ・ボット • 『鬼滅の刃』：妓夫太郎
A36: =IFERROR(__xludf.DUMMYFUNCTION("""COMPUTED_VALUE"""),"va_045") -> va_045 | B36: =IFERROR(__xludf.DUMMYFUNCTION("""COMPUTED_VALUE"""),"小野賢章") -> 小野賢章 | C36: =IFERROR(__xludf.DUMMYFUNCTION("""COMPUTED_VALUE"""),"T") -> T | D36: =IFERROR(__xludf.DUMMYFUNCTION("""COMPUTED_VALUE"""),"表示") -> 表示 | E36: =IFERROR(__xludf.DUMMYFUNCTION("""COMPUTED_VALUE"""),14) -> 14 | F36: =IFERROR(__xludf.DUMMYFUNCTION("""COMPUTED_VALUE"""),"• 『黒子のバスケ』：黒子テツヤ • 『アイドリッシュセブン』：七瀬陸 • 『文豪ストレイドッグス』：芥川龍之介 • 『ジョジョの奇妙な冒険 黄金の風』：ジョルノ・ジョバァーナ • 『ハリー・ポッター』シリーズ：ハリー・ポッター • 『SPY×FAMILY』：ユーリ・ブライア • 『ツルネ ―風舞高校弓道部―』：藤原愁") -> • 『黒子のバスケ』：黒子テツヤ • 『アイドリッシュセブン』：七瀬陸 • 『文豪ストレイドッグス』：芥川龍之介 • 『ジョジョの奇妙な冒険 黄金の風』：ジョルノ・ジョバァーナ • 『ハリー・ポッター』シリーズ：ハリー・ポッター • 『SPY×FAMILY』：ユーリ・ブライア • 『ツルネ ―風舞高校弓道部―』：藤原愁
A37: =IFERROR(__xludf.DUMMYFUNCTION("""COMPUTED_VALUE"""),"va_053") -> va_053 | B37: =IFERROR(__xludf.DUMMYFUNCTION("""COMPUTED_VALUE"""),"梶原岳人") -> 梶原岳人 | C37: =IFERROR(__xludf.DUMMYFUNCTION("""COMPUTED_VALUE"""),"T") -> T | D37: =IFERROR(__xludf.DUMMYFUNCTION("""COMPUTED_VALUE"""),"表示") -> 表示 | E37: =IFERROR(__xludf.DUMMYFUNCTION("""COMPUTED_VALUE"""),14) -> 14 | F37: =IFERROR(__xludf.DUMMYFUNCTION("""COMPUTED_VALUE"""),"• 『ブラッククローバー』：アスタ • 『炎炎ノ消防隊』：森羅日下部 • 『あんさんぶるスターズ！！』：天城一彩 • 『Paradox Live』：朱雀野アレン • 『お前はまだグンマを知らない』：神月紀") -> • 『ブラッククローバー』：アスタ • 『炎炎ノ消防隊』：森羅日下部 • 『あんさんぶるスターズ！！』：天城一彩 • 『Paradox Live』：朱雀野アレン • 『お前はまだグンマを知らない』：神月紀
A38: =IFERROR(__xludf.DUMMYFUNCTION("""COMPUTED_VALUE"""),"va_078") -> va_078 | B38: =IFERROR(__xludf.DUMMYFUNCTION("""COMPUTED_VALUE"""),"小西克幸") -> 小西克幸 | C38: =IFERROR(__xludf.DUMMYFUNCTION("""COMPUTED_VALUE"""),"T") -> T | D38: =IFERROR(__xludf.DUMMYFUNCTION("""COMPUTED_VALUE"""),"表示") -> 表示 | E38: =IFERROR(__xludf.DUMMYFUNCTION("""COMPUTED_VALUE"""),14) -> 14 | F38: =IFERROR(__xludf.DUMMYFUNCTION("""COMPUTED_VALUE"""),"• 『鬼滅の刃』：宇髄天元 • 『ヘタリア』：アメリカ • 『テイルズ オブ シンフォニア』：ロイド・アーヴィング • 『べるぜバブ』：男鹿辰巳 • 『ゴールデンカムイ』：鯉登音之進 • 『薬屋のひとりごと』：高順 • 『天元突破グレンラガン』：カミナ") -> • 『鬼滅の刃』：宇髄天元 • 『ヘタリア』：アメリカ • 『テイルズ オブ シンフォニア』：ロイド・アーヴィング • 『べるぜバブ』：男鹿辰巳 • 『ゴールデンカムイ』：鯉登音之進 • 『薬屋のひとりごと』：高順 • 『天元突破グレンラガン』：カミナ
A39: =IFERROR(__xludf.DUMMYFUNCTION("""COMPUTED_VALUE"""),"va_081") -> va_081 | B39: =IFERROR(__xludf.DUMMYFUNCTION("""COMPUTED_VALUE"""),"近藤隆") -> 近藤隆 | C39: =IFERROR(__xludf.DUMMYFUNCTION("""COMPUTED_VALUE"""),"T") -> T | D39: =IFERROR(__xludf.DUMMYFUNCTION("""COMPUTED_VALUE"""),"表示") -> 表示 | E39: =IFERROR(__xludf.DUMMYFUNCTION("""COMPUTED_VALUE"""),14) -> 14 | F39: =IFERROR(__xludf.DUMMYFUNCTION("""COMPUTED_VALUE"""),"• 『家庭教師ヒットマンREBORN!』：雲雀恭弥 • 『アイドリッシュセブン』：御堂虎於 • 『世界一初恋』：小野寺律 • 『DIABOLIK LOVERS』：逆巻スバル • 『ツキウタ。』：長月夜 • 『BLACK CAT』：トレイン＝ハートネット") -> • 『家庭教師ヒットマンREBORN!』：雲雀恭弥 • 『アイドリッシュセブン』：御堂虎於 • 『世界一初恋』：小野寺律 • 『DIABOLIK LOVERS』：逆巻スバル • 『ツキウタ。』：長月夜 • 『BLACK CAT』：トレイン＝ハートネット
A40: =IFERROR(__xludf.DUMMYFUNCTION("""COMPUTED_VALUE"""),"va_129") -> va_129 | B40: =IFERROR(__xludf.DUMMYFUNCTION("""COMPUTED_VALUE"""),"土岐隼一") -> 土岐隼一 | C40: =IFERROR(__xludf.DUMMYFUNCTION("""COMPUTED_VALUE"""),"T") -> T | D40: =IFERROR(__xludf.DUMMYFUNCTION("""COMPUTED_VALUE"""),"表示") -> 表示 | E40: =IFERROR(__xludf.DUMMYFUNCTION("""COMPUTED_VALUE"""),14) -> 14 | F40: =IFERROR(__xludf.DUMMYFUNCTION("""COMPUTED_VALUE"""),"• 『プロジェクトセカイ カラフルステージ！ feat. 初音ミク』：神代類 • 『アイドルマスター SideM』：都築圭 • 『ツキプロ』：衛藤昂輝 • 『A3!』：瑠璃川幸 • 『かくりよの宿飯』：銀次 • 『Paradox Live』：征木北斎 • 『原神』：フレミネ") -> • 『プロジェクトセカイ カラフルステージ！ feat. 初音ミク』：神代類 • 『アイドルマスター SideM』：都築圭 • 『ツキプロ』：衛藤昂輝 • 『A3!』：瑠璃川幸 • 『かくりよの宿飯』：銀次 • 『Paradox Live』：征木北斎 • 『原神』：フレミネ
...

Sheet 代表作一覧
A1: 声優名 | B1: 代表作
A2: =IFERROR(__xludf.DUMMYFUNCTION("FILTER({'声優一覧'!B2:B1000, '声優一覧'!F2:F1000}, '声優一覧'!C2:C1000=""T"")"),"赤羽根健治") -> 赤羽根健治 | B2: =IFERROR(__xludf.DUMMYFUNCTION("""COMPUTED_VALUE"""),"• 『真マジンガー 衝撃! Z編』：兜甲児 • 『THE IDOLM@STER』：プロデューサー • 『ジュエルペット てぃんくる☆』：レオン • 『宇崎ちゃんは遊びたい！』：桜井真一 • 『世界最高の暗殺者、異世界貴族に転生する』：ルーグ") -> • 『真マジンガー 衝撃! Z編』：兜甲児 • 『THE IDOLM@STER』：プロデューサー • 『ジュエルペット てぃんくる☆』：レオン • 『宇崎ちゃんは遊びたい！』：桜井真一 • 『世界最高の暗殺者、異世界貴族に転生する』：ルーグ
A3: =IFERROR(__xludf.DUMMYFUNCTION("""COMPUTED_VALUE"""),"阿座上洋平") -> 阿座上洋平 | B3: =IFERROR(__xludf.DUMMYFUNCTION("""COMPUTED_VALUE"""),"• 『機動戦士ガンダム 水星の魔女』：グエル・ジェターク • 『あんさんぶるスターズ！！』：天城燐音 • 『クロムクロ』：青馬剣之介時貞 • 『鴨乃橋ロンの禁断推理』：鴨乃橋ロン") -> • 『機動戦士ガンダム 水星の魔女』：グエル・ジェターク • 『あんさんぶるスターズ！！』：天城燐音 • 『クロムクロ』：青馬剣之介時貞 • 『鴨乃橋ロンの禁断推理』：鴨乃橋ロン
A4: =IFERROR(__xludf.DUMMYFUNCTION("""COMPUTED_VALUE"""),"浅沼晋太郎") -> 浅沼晋太郎 | B4: =IFERROR(__xludf.DUMMYFUNCTION("""COMPUTED_VALUE"""),"• 『ヒプノシスマイク』：碧棺左馬刻 • 『あんさんぶるスターズ！』：月永レオ • 『生徒会役員共』：津田タカトシ • 『ダイヤのA』：倉持洋一 • 『ギヴン』：村田雨月") -> • 『ヒプノシスマイク』：碧棺左馬刻 • 『あんさんぶるスターズ！』：月永レオ • 『生徒会役員共』：津田タカトシ • 『ダイヤのA』：倉持洋一 • 『ギヴン』：村田雨月
A5: =IFERROR(__xludf.DUMMYFUNCTION("""COMPUTED_VALUE"""),"浅利遼太") -> 浅利遼太 | B5: =IFERROR(__xludf.DUMMYFUNCTION("""COMPUTED_VALUE"""),"• 『刀剣乱舞』：平野藤四郎／明石国行／ソハヤノツルキ • 『ワールドトリガー』：小荒井登 • 『D.Gray-man HALLOW』：アルマ＝カルマ • 『妖怪ウォッチ』：砂夫／土蜘蛛 • 『呪術廻戦』：新田新") -> • 『刀剣乱舞』：平野藤四郎／明石国行／ソハヤノツルキ • 『ワールドトリガー』：小荒井登 • 『D.Gray-man HALLOW』：アルマ＝カルマ • 『妖怪ウォッチ』：砂夫／土蜘蛛 • 『呪術廻戦』：新田新
A6: =IFERROR(__xludf.DUMMYFUNCTION("""COMPUTED_VALUE"""),"阿部敦") -> 阿部敦 | B6: =IFERROR(__xludf.DUMMYFUNCTION("""COMPUTED_VALUE"""),"• 『とある魔術の禁書目録』／『とある科学の超電磁砲』：上条当麻 • 『バクマン。』：真城最高 • 『アイドリッシュセブン』：逢坂壮五 • 『しゅごキャラ！』：相馬空海 • 『弱虫ペダル』：泉田塔一郎") -> • 『とある魔術の禁書目録』／『とある科学の超電磁砲』：上条当麻 • 『バクマン。』：真城最高 • 『アイドリッシュセブン』：逢坂壮五 • 『しゅごキャラ！』：相馬空海 • 『弱虫ペダル』：泉田塔一郎
A7: =IFERROR(__xludf.DUMMYFUNCTION("""COMPUTED_VALUE"""),"天﨑滉平") -> 天﨑滉平 | B7: =IFERROR(__xludf.DUMMYFUNCTION("""COMPUTED_VALUE"""),"• 『ヒプノシスマイク』：山田三郎 • 『Re:ゼロから始める異世界生活』：オットー・スーウェン • 『ハイスコアガール』：矢口春雄 • 『僕のヒーローアカデミア』：物間寧人 • 『あんさんぶるスターズ！！』：白鳥藍良") -> • 『ヒプノシスマイク』：山田三郎 • 『Re:ゼロから始める異世界生活』：オットー・スーウェン • 『ハイスコアガール』：矢口春雄 • 『僕のヒーローアカデミア』：物間寧人 • 『あんさんぶるスターズ！！』：白鳥藍良
A8: =IFERROR(__xludf.DUMMYFUNCTION("""COMPUTED_VALUE"""),"蒼井翔太") -> 蒼井翔太 | B8: =IFERROR(__xludf.DUMMYFUNCTION("""COMPUTED_VALUE"""),"• 『うたの☆プリンスさまっ♪』：美風藍 • 『KING OF PRISM』：如月ルヰ • 『乙女ゲームの破滅フラグしかない悪役令嬢に転生してしまった…』：ジオルド・スティアート • 『ツキウタ。』：水無月涙 • 『ヴィジュアルプリズン』：ハイド・ジャイエ") -> • 『うたの☆プリンスさまっ♪』：美風藍 • 『KING OF PRISM』：如月ルヰ • 『乙女ゲームの破滅フラグしかない悪役令嬢に転生してしまった…』：ジオルド・スティアート • 『ツキウタ。』：水無月涙 • 『ヴィジュアルプリズン』：ハイド・ジャイエ
A9: =IFERROR(__xludf.DUMMYFUNCTION("""COMPUTED_VALUE"""),"井口祐一") -> 井口祐一 | B9: =IFERROR(__xludf.DUMMYFUNCTION("""COMPUTED_VALUE"""),"• 『僕らはみんな河合荘』：宇佐和成 • 『はたらく魔王さま！』：猿江三月／サリエル • 『FAIRY TAIL』：マックス • 『Spiritpact』：楊敬華 • 『BEASTARS』：キビ") -> • 『僕らはみんな河合荘』：宇佐和成 • 『はたらく魔王さま！』：猿江三月／サリエル • 『FAIRY TAIL』：マックス • 『Spiritpact』：楊敬華 • 『BEASTARS』：キビ
A10: =IFERROR(__xludf.DUMMYFUNCTION("""COMPUTED_VALUE"""),"石川界人") -> 石川界人 | B10: =IFERROR(__xludf.DUMMYFUNCTION("""COMPUTED_VALUE"""),"• 『ハイキュー!!』：影山飛雄 • 『ワンパンマン』：ジェノス • 『僕のヒーローアカデミア』：飯田天哉 • 『盾の勇者の成り上がり』：岩谷尚文 • 『青春ブタ野郎シリーズ』：梓川咲太 • 『わたしの幸せな結婚』：久堂清霞") -> • 『ハイキュー!!』：影山飛雄 • 『ワンパンマン』：ジェノス • 『僕のヒーローアカデミア』：飯田天哉 • 『盾の勇者の成り上がり』：岩谷尚文 • 『青春ブタ野郎シリーズ』：梓川咲太 • 『わたしの幸せな結婚』：久堂清霞
A11: =IFERROR(__xludf.DUMMYFUNCTION("""COMPUTED_VALUE"""),"石谷春貴") -> 石谷春貴 | B11: =IFERROR(__xludf.DUMMYFUNCTION("""COMPUTED_VALUE"""),"• 『響け！ユーフォニアム』：塚本秀一 • 『ヒプノシスマイク』：山田二郎 • 『AKIBA’S TRIP -THE ANIMATION-』：伝木凱タモツ • 『ぼくたちのリメイク』：鹿苑寺貫之 • 『この音とまれ！』：足立実康") -> • 『響け！ユーフォニアム』：塚本秀一 • 『ヒプノシスマイク』：山田二郎 • 『AKIBA’S TRIP -THE ANIMATION-』：伝木凱タモツ • 『ぼくたちのリメイク』：鹿苑寺貫之 • 『この音とまれ！』：足立実康
A12: =IFERROR(__xludf.DUMMYFUNCTION("""COMPUTED_VALUE"""),"市川蒼") -> 市川蒼 | B12: =IFERROR(__xludf.DUMMYFUNCTION("""COMPUTED_VALUE"""),"• 『Just Because!』：泉瑛太 • 『ダーリン・イン・ザ・フランキス』：ミツル • 『ツルネ ―風舞高校弓道部―』：竹早静弥 • 『ブルーロック』：五十嵐栗夢 • 『地獄楽』：山田浅ェ門付知 • 『ディズニー ツイステッドワンダーランド』：ラギー・ブッチ") -> • 『Just Because!』：泉瑛太 • 『ダーリン・イン・ザ・フランキス』：ミツル • 『ツルネ ―風舞高校弓道部―』：竹早静弥 • 『ブルーロック』：五十嵐栗夢 • 『地獄楽』：山田浅ェ門付知 • 『ディズニー ツイステッドワンダーランド』：ラギー・ブッチ
A13: =IFERROR(__xludf.DUMMYFUNCTION("""COMPUTED_VALUE"""),"市川太一") -> 市川太一 | B13: =IFERROR(__xludf.DUMMYFUNCTION("""COMPUTED_VALUE"""),"• 『カブキブ！』：来栖黒悟 • 『やがて君になる』：槙聖司 • 『終末のハーレム』：水原怜人 • 『時々ボソッとロシア語でデレる隣のアーリャさん』：清宮光瑠") -> • 『カブキブ！』：来栖黒悟 • 『やがて君になる』：槙聖司 • 『終末のハーレム』：水原怜人 • 『時々ボソッとロシア語でデレる隣のアーリャさん』：清宮光瑠
A14: =IFERROR(__xludf.DUMMYFUNCTION("""COMPUTED_VALUE"""),"市来光弘") -> 市来光弘 | B14: =IFERROR(__xludf.DUMMYFUNCTION("""COMPUTED_VALUE"""),"• 『刀剣乱舞』：大和守安定 • 『スクールランブル』：麻生広義 • 『会長はメイド様！』：白川直也 • 『ドロヘドロ』：カスカベ • 『佐々木と宮野』：田代権三郎 • 『八十亀ちゃんかんさつにっき』：陣界斗") -> • 『刀剣乱舞』：大和守安定 • 『スクールランブル』：麻生広義 • 『会長はメイド様！』：白川直也 • 『ドロヘドロ』：カスカベ • 『佐々木と宮野』：田代権三郎 • 『八十亀ちゃんかんさつにっき』：陣界斗
A15: =IFERROR(__xludf.DUMMYFUNCTION("""COMPUTED_VALUE"""),"伊東健人") -> 伊東健人 | B15: =IFERROR(__xludf.DUMMYFUNCTION("""COMPUTED_VALUE"""),"• 『ヲタクに恋は難しい』：二藤宏嵩 • 『【推しの子】』：ゴロー • 『ヒプノシスマイク』：観音坂独歩 • 『アイドルマスター SideM』：硲道夫 • 『プロジェクトセカイ カラフルステージ！』：青柳冬弥") -> • 『ヲタクに恋は難しい』：二藤宏嵩 • 『【推しの子】』：ゴロー • 『ヒプノシスマイク』：観音坂独歩 • 『アイドルマスター SideM』：硲道夫 • 『プロジェクトセカイ カラフルステージ！』：青柳冬弥
A16: =IFERROR(__xludf.DUMMYFUNCTION("""COMPUTED_VALUE"""),"井上和彦") -> 井上和彦 | B16: =IFERROR(__xludf.DUMMYFUNCTION("""COMPUTED_VALUE"""),"• 『NARUTO -ナルト-』：はたけカカシ • 『夏目友人帳』：ニャンコ先生／斑 • 『美味しんぼ』：山岡士郎 • 『サイボーグ009』：島村ジョー • 『機動戦士Ζガンダム』：ジェリド・メサ • 『名探偵コナン』：白鳥任三郎") -> • 『NARUTO -ナルト-』：はたけカカシ • 『夏目友人帳』：ニャンコ先生／斑 • 『美味しんぼ』：山岡士郎 • 『サイボーグ009』：島村ジョー • 『機動戦士Ζガンダム』：ジェリド・メサ • 『名探偵コナン』：白鳥任三郎
A17: =IFERROR(__xludf.DUMMYFUNCTION("""COMPUTED_VALUE"""),"井上雄貴") -> 井上雄貴 | B17: =IFERROR(__xludf.DUMMYFUNCTION("""COMPUTED_VALUE"""),"• 『天使の3P!』：貫井響 • 『かくりよの宿飯』：サスケ • 『アトム ザ・ビギニング』：A106 • 『月刊モー想科学』：ノイン • 『ハイキュー!!』：姫川葵") -> • 『天使の3P!』：貫井響 • 『かくりよの宿飯』：サスケ • 『アトム ザ・ビギニング』：A106 • 『月刊モー想科学』：ノイン • 『ハイキュー!!』：姫川葵
A18: =IFERROR(__xludf.DUMMYFUNCTION("""COMPUTED_VALUE"""),"今井文也") -> 今井文也 | B18: =IFERROR(__xludf.DUMMYFUNCTION("""COMPUTED_VALUE"""),"• 『ギヴン』：鹿島柊 • 『神クズ☆アイドル』：仁淀ユウヤ • 『プロジェクトセカイ カラフルステージ！』：東雲彰人 • 『ハナビちゃんは遅れがち』：東雲ムサシ • 『A3!』：木之崎レント") -> • 『ギヴン』：鹿島柊 • 『神クズ☆アイドル』：仁淀ユウヤ • 『プロジェクトセカイ カラフルステージ！』：東雲彰人 • 『ハナビちゃんは遅れがち』：東雲ムサシ • 『A3!』：木之崎レント
A19: =IFERROR(__xludf.DUMMYFUNCTION("""COMPUTED_VALUE"""),"入江玲於奈") -> 入江玲於奈 | B19: =IFERROR(__xludf.DUMMYFUNCTION("""COMPUTED_VALUE"""),"• 『刀剣乱舞』：前田藤四郎 • 『プリンスPiaキャロット』：立花心路 • 『でみめん』：サタン • 『乙女剣武蔵』：宍戸梅軒") -> • 『刀剣乱舞』：前田藤四郎 • 『プリンスPiaキャロット』：立花心路 • 『でみめん』：サタン • 『乙女剣武蔵』：宍戸梅軒
A20: =IFERROR(__xludf.DUMMYFUNCTION("""COMPUTED_VALUE"""),"入野自由") -> 入野自由 | B20: =IFERROR(__xludf.DUMMYFUNCTION("""COMPUTED_VALUE"""),"• 『おそ松さん』：松野トド松 • 『ハイキュー!!』：菅原孝支 • 『千と千尋の神隠し』：ハク • 『キングダム ハーツ』：ソラ • 『アイシールド21』：小早川瀬那 • 『あの日見た花の名前を僕達はまだ知らない。』：宿海仁太") -> • 『おそ松さん』：松野トド松 • 『ハイキュー!!』：菅原孝支 • 『千と千尋の神隠し』：ハク • 『キングダム ハーツ』：ソラ • 『アイシールド21』：小早川瀬那 • 『あの日見た花の名前を僕達はまだ知らない。』：宿海仁太
A21: =IFERROR(__xludf.DUMMYFUNCTION("""COMPUTED_VALUE"""),"岩崎諒太") -> 岩崎諒太 | B21: =IFERROR(__xludf.DUMMYFUNCTION("""COMPUTED_VALUE"""),"• 『ヒプノシスマイク』：白膠木簓 • 『僕のヒーローアカデミア』：夜嵐イナサ • 『ザ・ファブル』：黒塩遼 • 『柚木さんちの四兄弟。』：柚木隼 • 『からくりサーカス』：仲町紀之") -> • 『ヒプノシスマイク』：白膠木簓 • 『僕のヒーローアカデミア』：夜嵐イナサ • 『ザ・ファブル』：黒塩遼 • 『柚木さんちの四兄弟。』：柚木隼 • 『からくりサーカス』：仲町紀之
A22: =IFERROR(__xludf.DUMMYFUNCTION("""COMPUTED_VALUE"""),"岩中睦樹") -> 岩中睦樹 | B22: =IFERROR(__xludf.DUMMYFUNCTION("""COMPUTED_VALUE"""),"• 『月がきれい』：立花大輔 • 『ようこそ実力至上主義の教室へ』：山内春樹 • 『キャプテン翼』：井沢守 • 『AIの遺電子』：ジェイ • 『ネガポジアングラー』：佐々木常宏 • 『妻、小学生になる。』：愛川蓮司") -> • 『月がきれい』：立花大輔 • 『ようこそ実力至上主義の教室へ』：山内春樹 • 『キャプテン翼』：井沢守 • 『AIの遺電子』：ジェイ • 『ネガポジアングラー』：佐々木常宏 • 『妻、小学生になる。』：愛川蓮司
A23: =IFERROR(__xludf.DUMMYFUNCTION("""COMPUTED_VALUE"""),"上村祐翔") -> 上村祐翔 | B23: =IFERROR(__xludf.DUMMYFUNCTION("""COMPUTED_VALUE"""),"• 『文豪ストレイドッグス』：中島敦 • 『ダーリン・イン・ザ・フランキス』：ヒロ • 『僕のヒーローアカデミア』：天喰環 • 『ヴィンランド・サガ』：トルフィン • 『ツルネ ―風舞高校弓道部―』：鳴宮湊 • 『B-PROJECT』：増長和南") -> • 『文豪ストレイドッグス』：中島敦 • 『ダーリン・イン・ザ・フランキス』：ヒロ • 『僕のヒーローアカデミア』：天喰環 • 『ヴィンランド・サガ』：トルフィン • 『ツルネ ―風舞高校弓道部―』：鳴宮湊 • 『B-PROJECT』：増長和南
A24: =IFERROR(__xludf.DUMMYFUNCTION("""COMPUTED_VALUE"""),"内田修一") -> 内田修一 | B24: =IFERROR(__xludf.DUMMYFUNCTION("""COMPUTED_VALUE"""),"• 『灼熱カバディ』：栄倉祐 • 『カミエラビ GOD.app』：秋津豊 • 『転生貴族、鑑定スキルで成り上がる』：ブラッハム・ジョー • 『その着せ替え人形は恋をする』：森田健星 • 『夫婦以上、恋人未満。』：寺船周 • 『アンダーニンジャ』：瑛太") -> • 『灼熱カバディ』：栄倉祐 • 『カミエラビ GOD.app』：秋津豊 • 『転生貴族、鑑定スキルで成り上がる』：ブラッハム・ジョー • 『その着せ替え人形は恋をする』：森田健星 • 『夫婦以上、恋人未満。』：寺船周 • 『アンダーニンジャ』：瑛太
A25: =IFERROR(__xludf.DUMMYFUNCTION("""COMPUTED_VALUE"""),"内田雄馬") -> 内田雄馬 | B25: =IFERROR(__xludf.DUMMYFUNCTION("""COMPUTED_VALUE"""),"• 『呪術廻戦』：伏黒恵 • 『BANANA FISH』：アッシュ・リンクス • 『ブルーロック』：御影玲王 • 『WIND BREAKER』：桜遥 • 『フルーツバスケット』：草摩夾 • 『マクロスΔ』：ハヤテ・インメルマン • 『りゅうおうのおしごと！』：九頭竜八一") -> • 『呪術廻戦』：伏黒恵 • 『BANANA FISH』：アッシュ・リンクス • 『ブルーロック』：御影玲王 • 『WIND BREAKER』：桜遥 • 『フルーツバスケット』：草摩夾 • 『マクロスΔ』：ハヤテ・インメルマン • 『りゅうおうのおしごと！』：九頭竜八一
A26: =IFERROR(__xludf.DUMMYFUNCTION("""COMPUTED_VALUE"""),"内山昂輝") -> 内山昂輝 | B26: =IFERROR(__xludf.DUMMYFUNCTION("""COMPUTED_VALUE"""),"• 『ハイキュー!!』：月島蛍 • 『僕のヒーローアカデミア』：死柄木弔 • 『呪術廻戦』：狗巻棘 • 『機動戦士ガンダムUC』：バナージ・リンクス • 『Free!』：桐嶋郁弥 • 『キングダム ハーツ』：ロクサス／ヴェントゥス • 『ホリミヤ』：宮村伊澄") -> • 『ハイキュー!!』：月島蛍 • 『僕のヒーローアカデミア』：死柄木弔 • 『呪術廻戦』：狗巻棘 • 『機動戦士ガンダムUC』：バナージ・リンクス • 『Free!』：桐嶋郁弥 • 『キングダム ハーツ』：ロクサス／ヴェントゥス • 『ホリミヤ』：宮村伊澄
A27: =IFERROR(__xludf.DUMMYFUNCTION("""COMPUTED_VALUE"""),"梅田修一朗") -> 梅田修一朗 | B27: =IFERROR(__xludf.DUMMYFUNCTION("""COMPUTED_VALUE"""),"• 『可愛いだけじゃない式守さん』：和泉くん • 『魔法使い黎明期』：セービル • 『ゾンビ100～ゾンビになるまでにしたい100のこと～』：天道輝 • 『負けヒロインが多すぎる！』：温水和彦 • 『光が死んだ夏』：ヒカル • 『ヴィジランテ -僕のヒーローアカデミア ILLEGALS-』：灰廻航一") -> • 『可愛いだけじゃない式守さん』：和泉くん • 『魔法使い黎明期』：セービル • 『ゾンビ100～ゾンビになるまでにしたい100のこと～』：天道輝 • 『負けヒロインが多すぎる！』：温水和彦 • 『光が死んだ夏』：ヒカル • 『ヴィジランテ -僕のヒーローアカデミア ILLEGALS-』：灰廻航一
A28: =IFERROR(__xludf.DUMMYFUNCTION("""COMPUTED_VALUE"""),"梅原裕一郎") -> 梅原裕一郎 | B28: =IFERROR(__xludf.DUMMYFUNCTION("""COMPUTED_VALUE"""),"• 『ゴブリンスレイヤー』：ゴブリンスレイヤー • 『美男高校地球防衛部LOVE!』：由布院煙 • 『あんさんぶるスターズ！』：蓮巳敬人 • 『アイドルマスター SideM』：鷹城恭二 • 『魔王学院の不適合者』：アノス・ヴォルディゴード • 『WIND BREAKER』：十亀条 • 『ディズニー ツイステッドワンダーランド』：レオナ・キングスカラー") -> • 『ゴブリンスレイヤー』：ゴブリンスレイヤー • 『美男高校地球防衛部LOVE!』：由布院煙 • 『あんさんぶるスターズ！』：蓮巳敬人 • 『アイドルマスター SideM』：鷹城恭二 • 『魔王学院の不適合者』：アノス・ヴォルディゴード • 『WIND BREAKER』：十亀条 • 『ディズニー ツイステッドワンダーランド』：レオナ・キングスカラー
A29: =IFERROR(__xludf.DUMMYFUNCTION("""COMPUTED_VALUE"""),"浦和希") -> 浦和希 | B29: =IFERROR(__xludf.DUMMYFUNCTION("""COMPUTED_VALUE"""),"• 『ブルーロック』：潔世一 • 『シャドウバースF』：真壁スバル • 『テクノロイド オーバーマインド』：コバルト • 『桃源暗鬼』：一ノ瀬四季 • 『カミエラビ GOD.app』：ゴロー • 『悪魔執事と黒い猫』：ナック・シュタイン") -> • 『ブルーロック』：潔世一 • 『シャドウバースF』：真壁スバル • 『テクノロイド オーバーマインド』：コバルト • 『桃源暗鬼』：一ノ瀬四季 • 『カミエラビ GOD.app』：ゴロー • 『悪魔執事と黒い猫』：ナック・シュタイン
A30: =IFERROR(__xludf.DUMMYFUNCTION("""COMPUTED_VALUE"""),"江口拓也") -> 江口拓也 | B30: =IFERROR(__xludf.DUMMYFUNCTION("""COMPUTED_VALUE"""),"• 『SPY×FAMILY』：ロイド・フォージャー • 『やはり俺の青春ラブコメはまちがっている。』：比企谷八幡 • 『アイドリッシュセブン』：六弥ナギ • 『東京リベンジャーズ』：半間修二 • 『転生したらスライムだった件』：ソウエイ • 『マッシュル-MASHLE-』：ドット・バレット • 『あんさんぶるスターズ！』：日々樹渉") -> • 『SPY×FAMILY』：ロイド・フォージャー • 『やはり俺の青春ラブコメはまちがっている。』：比企谷八幡 • 『アイドリッシュセブン』：六弥ナギ • 『東京リベンジャーズ』：半間修二 • 『転生したらスライムだった件』：ソウエイ • 『マッシュル-MASHLE-』：ドット・バレット • 『あんさんぶるスターズ！』：日々樹渉
A31: =IFERROR(__xludf.DUMMYFUNCTION("""COMPUTED_VALUE"""),"榎木淳弥") -> 榎木淳弥 | B31: =IFERROR(__xludf.DUMMYFUNCTION("""COMPUTED_VALUE"""),"• 『呪術廻戦』：虎杖悠仁 • 『ジョジョの奇妙な冒険 黄金の風』：パンナコッタ・フーゴ • 『トニカクカワイイ』：由崎星空 • 『アイドルマスター SideM』：舞田類 • 『め組の大吾 救国のオレンジ』：十朱大吾") -> • 『呪術廻戦』：虎杖悠仁 • 『ジョジョの奇妙な冒険 黄金の風』：パンナコッタ・フーゴ • 『トニカクカワイイ』：由崎星空 • 『アイドルマスター SideM』：舞田類 • 『め組の大吾 救国のオレンジ』：十朱大吾
A32: =IFERROR(__xludf.DUMMYFUNCTION("""COMPUTED_VALUE"""),"逢坂良太") -> 逢坂良太 | B32: =IFERROR(__xludf.DUMMYFUNCTION("""COMPUTED_VALUE"""),"• 『ダイヤのA』：沢村栄純 • 『はたらく魔王さま！』：真奥貞夫（魔王サタン） • 『ハイキュー!!』：赤葦京治 • 『あんさんぶるスターズ！！』：七種茨 • 『赤髪の白雪姫』：ゼン • 『進撃の巨人』：マルコ・ボット • 『鬼滅の刃』：妓夫太郎") -> • 『ダイヤのA』：沢村栄純 • 『はたらく魔王さま！』：真奥貞夫（魔王サタン） • 『ハイキュー!!』：赤葦京治 • 『あんさんぶるスターズ！！』：七種茨 • 『赤髪の白雪姫』：ゼン • 『進撃の巨人』：マルコ・ボット • 『鬼滅の刃』：妓夫太郎
A33: =IFERROR(__xludf.DUMMYFUNCTION("""COMPUTED_VALUE"""),"小笠原仁") -> 小笠原仁 | B33: =IFERROR(__xludf.DUMMYFUNCTION("""COMPUTED_VALUE"""),"• 『from ARGONAVIS』：旭那由多 • 『カードファイト!! ヴァンガード will+Dress』：狐芝ライカ • 『WAVE!!～サーフィンやっぺ!!～』：秋月ショウ • 『カワイスギクライシス』：向井誠二 • 『18TRIP』：西園練牙 • 『SSSS.DYNAZENON』：淡木") -> • 『from ARGONAVIS』：旭那由多 • 『カードファイト!! ヴァンガード will+Dress』：狐芝ライカ • 『WAVE!!～サーフィンやっぺ!!～』：秋月ショウ • 『カワイスギクライシス』：向井誠二 • 『18TRIP』：西園練牙 • 『SSSS.DYNAZENON』：淡木
A34: =IFERROR(__xludf.DUMMYFUNCTION("""COMPUTED_VALUE"""),"大須賀純") -> 大須賀純 | B34: =IFERROR(__xludf.DUMMYFUNCTION("""COMPUTED_VALUE"""),"• 『あんさんぶるスターズ！』：影片みか • 『刀剣乱舞』：博多藤四郎 • 『新テニスの王子様』：千歳千里 • 『サンリオ男子』：吉野俊介 • 『おおきく振りかぶって』：叶修悟 • 『PJベリーのもぐもぐむにゃむにゃ』：PJベリー") -> • 『あんさんぶるスターズ！』：影片みか • 『刀剣乱舞』：博多藤四郎 • 『新テニスの王子様』：千歳千里 • 『サンリオ男子』：吉野俊介 • 『おおきく振りかぶって』：叶修悟 • 『PJベリーのもぐもぐむにゃむにゃ』：PJベリー
A35: =IFERROR(__xludf.DUMMYFUNCTION("""COMPUTED_VALUE"""),"大谷祐貴") -> 大谷祐貴 | B35: =IFERROR(__xludf.DUMMYFUNCTION("""COMPUTED_VALUE"""),"• 『巨神と氷華の城』：志郎 • 『刀剣乱舞』：太閤左文字 • 『デリシャスパーティ♡プリキュア』：青山のりお") -> • 『巨神と氷華の城』：志郎 • 『刀剣乱舞』：太閤左文字 • 『デリシャスパーティ♡プリキュア』：青山のりお
A36: =IFERROR(__xludf.DUMMYFUNCTION("""COMPUTED_VALUE"""),"大塚剛央") -> 大塚剛央 | B36: =IFERROR(__xludf.DUMMYFUNCTION("""COMPUTED_VALUE"""),"• 『【推しの子】』：アクア • 『薬屋のひとりごと』：壬氏 • 『風が強く吹いている』：蔵原走 • 『アイドルマスター SideM』：眉見鋭心 • 『百千さん家のあやかし王子』：七守葵／鵺 • 『トリリオンゲーム』：天王寺陽") -> • 『【推しの子】』：アクア • 『薬屋のひとりごと』：壬氏 • 『風が強く吹いている』：蔵原走 • 『アイドルマスター SideM』：眉見鋭心 • 『百千さん家のあやかし王子』：七守葵／鵺 • 『トリリオンゲーム』：天王寺陽
A37: =IFERROR(__xludf.DUMMYFUNCTION("""COMPUTED_VALUE"""),"岡本信彦") -> 岡本信彦 | B37: =IFERROR(__xludf.DUMMYFUNCTION("""COMPUTED_VALUE"""),"• 『僕のヒーローアカデミア』：爆豪勝己 • 『青の祓魔師』：奥村燐 • 『とある魔術の禁書目録』：一方通行（アクセラレータ） • 『ハイキュー!!』：西谷夕 • 『暗殺教室』：赤羽業 • 『葬送のフリーレン』：ヒンメル • 『鬼滅の刃』：不死川玄弥") -> • 『僕のヒーローアカデミア』：爆豪勝己 • 『青の祓魔師』：奥村燐 • 『とある魔術の禁書目録』：一方通行（アクセラレータ） • 『ハイキュー!!』：西谷夕 • 『暗殺教室』：赤羽業 • 『葬送のフリーレン』：ヒンメル • 『鬼滅の刃』：不死川玄弥
A38: =IFERROR(__xludf.DUMMYFUNCTION("""COMPUTED_VALUE"""),"置鮎龍太郎") -> 置鮎龍太郎 | B38: =IFERROR(__xludf.DUMMYFUNCTION("""COMPUTED_VALUE"""),"• 『テニスの王子様』：手塚国光 • 『BLEACH』：朽木白哉 • 『SLAM DUNK』：三井寿 • 『地獄先生ぬ～べ～』：鵺野鳴介 • 『鋼の錬金術師』：スカー • 『トリコ』：トリコ • 『名探偵コナン』：沖矢昴") -> • 『テニスの王子様』：手塚国光 • 『BLEACH』：朽木白哉 • 『SLAM DUNK』：三井寿 • 『地獄先生ぬ～べ～』：鵺野鳴介 • 『鋼の錬金術師』：スカー • 『トリコ』：トリコ • 『名探偵コナン』：沖矢昴
A39: =IFERROR(__xludf.DUMMYFUNCTION("""COMPUTED_VALUE"""),"興津和幸") -> 興津和幸 | B39: =IFERROR(__xludf.DUMMYFUNCTION("""COMPUTED_VALUE"""),"• 『ジョジョの奇妙な冒険』：ジョナサン・ジョースター • 『アイドリッシュセブン』：大神万理 • 『BROTHERS CONFLICT』：朝日奈雅臣 • 『刀剣乱舞』：蜂須賀虎徹 • 『蒼き鋼のアルペジオ -アルス・ノヴァ-』：千早群像") -> • 『ジョジョの奇妙な冒険』：ジョナサン・ジョースター • 『アイドリッシュセブン』：大神万理 • 『BROTHERS CONFLICT』：朝日奈雅臣 • 『刀剣乱舞』：蜂須賀虎徹 • 『蒼き鋼のアルペジオ -アルス・ノヴァ-』：千早群像
A40: =IFERROR(__xludf.DUMMYFUNCTION("""COMPUTED_VALUE"""),"小野賢章") -> 小野賢章 | B40: =IFERROR(__xludf.DUMMYFUNCTION("""COMPUTED_VALUE"""),"• 『黒子のバスケ』：黒子テツヤ • 『アイドリッシュセブン』：七瀬陸 • 『文豪ストレイドッグス』：芥川龍之介 • 『ジョジョの奇妙な冒険 黄金の風』：ジョルノ・ジョバァーナ • 『ハリー・ポッター』シリーズ：ハリー・ポッター • 『SPY×FAMILY』：ユーリ・ブライア • 『ツルネ ―風舞高校弓道部―』：藤原愁") -> • 『黒子のバスケ』：黒子テツヤ • 『アイドリッシュセブン』：七瀬陸 • 『文豪ストレイドッグス』：芥川龍之介 • 『ジョジョの奇妙な冒険 黄金の風』：ジョルノ・ジョバァーナ • 『ハリー・ポッター』シリーズ：ハリー・ポッター • 『SPY×FAMILY』：ユーリ・ブライア • 『ツルネ ―風舞高校弓道部―』：藤原愁
...

Sheet キャラクター名
A1: 声優ID | B1: 声優名 | C1: 作品ID | D1: 作品名 | E1: キャラクター名
A2: {=IF(B2="", "", IFERROR(INDEX(声優一覧!A:A, MATCH(B2, 声優一覧!B:B, 0)), "該当なし"))} -> va_137 | B2: 中村悠一 | C2: touken | D2: =IF(C2="", "", IFERROR(VLOOKUP(C2, 作品一覧!A:B, 2, FALSE), "該当なし")) -> 刀剣乱舞 | E2: 童子切安綱 剥落
A3: {=IF(B3="", "", IFERROR(INDEX(声優一覧!A:A, MATCH(B3, 声優一覧!B:B, 0)), "該当なし"))} -> va_132 | B3: 鳥海浩輔 | C3: touken | D3: =IF(C3="", "", IFERROR(VLOOKUP(C3, 作品一覧!A:B, 2, FALSE), "該当なし")) -> 刀剣乱舞 | E3: 三日月宗近
A4: {=IF(B4="", "", IFERROR(INDEX(声優一覧!A:A, MATCH(B4, 声優一覧!B:B, 0)), "該当なし"))} -> va_081 | B4: 近藤隆 | C4: touken | D4: =IF(C4="", "", IFERROR(VLOOKUP(C4, 作品一覧!A:B, 2, FALSE), "該当なし")) -> 刀剣乱舞 | E4: 小狐丸
A5: {=IF(B5="", "", IFERROR(INDEX(声優一覧!A:A, MATCH(B5, 声優一覧!B:B, 0)), "該当なし"))} -> va_110 | B5: 高橋英則 | C5: touken | D5: =IF(C5="", "", IFERROR(VLOOKUP(C5, 作品一覧!A:B, 2, FALSE), "該当なし")) -> 刀剣乱舞 | E5: 石切丸
A6: {=IF(B6="", "", IFERROR(INDEX(声優一覧!A:A, MATCH(B6, 声優一覧!B:B, 0)), "該当なし"))} -> va_181 | B6: 宮下栄治 | C6: touken | D6: =IF(C6="", "", IFERROR(VLOOKUP(C6, 作品一覧!A:B, 2, FALSE), "該当なし")) -> 刀剣乱舞 | E6: 岩融
A7: {=IF(B7="", "", IFERROR(INDEX(声優一覧!A:A, MATCH(B7, 声優一覧!B:B, 0)), "該当なし"))} -> va_193 | B7: 山下大輝 | C7: touken | D7: =IF(C7="", "", IFERROR(VLOOKUP(C7, 作品一覧!A:B, 2, FALSE), "該当なし")) -> 刀剣乱舞 | E7: 今剣
A8: {=IF(B8="", "", IFERROR(INDEX(声優一覧!A:A, MATCH(B8, 声優一覧!B:B, 0)), "該当なし"))} -> va_138 | B8: 浪川大輔 | C8: touken | D8: =IF(C8="", "", IFERROR(VLOOKUP(C8, 作品一覧!A:B, 2, FALSE), "該当なし")) -> 刀剣乱舞 | E8: 大典太光世
A9: {=IF(B9="", "", IFERROR(INDEX(声優一覧!A:A, MATCH(B9, 声優一覧!B:B, 0)), "該当なし"))} -> va_005 | B9: 浅利遼太 | C9: touken | D9: =IF(C9="", "", IFERROR(VLOOKUP(C9, 作品一覧!A:B, 2, FALSE), "該当なし")) -> 刀剣乱舞 | E9: ソハヤノツルキ
A10: {=IF(B10="", "", IFERROR(INDEX(声優一覧!A:A, MATCH(B10, 声優一覧!B:B, 0)), "該当なし"))} -> va_180 | B10: 緑川光 | C10: touken | D10: =IF(C10="", "", IFERROR(VLOOKUP(C10, 作品一覧!A:B, 2, FALSE), "該当なし")) -> 刀剣乱舞 | E10: 数珠丸恒次
A11: {=IF(B11="", "", IFERROR(INDEX(声優一覧!A:A, MATCH(B11, 声優一覧!B:B, 0)), "該当なし"))} -> va_171 | B11: 間島淳司 | C11: touken | D11: =IF(C11="", "", IFERROR(VLOOKUP(C11, 作品一覧!A:B, 2, FALSE), "該当なし")) -> 刀剣乱舞 | E11: にっかり青江
A12: {=IF(B12="", "", IFERROR(INDEX(声優一覧!A:A, MATCH(B12, 声優一覧!B:B, 0)), "該当なし"))} -> va_186 | B12: 森川智之 | C12: touken | D12: =IF(C12="", "", IFERROR(VLOOKUP(C12, 作品一覧!A:B, 2, FALSE), "該当なし")) -> 刀剣乱舞 | E12: 鬼丸国綱
A13: {=IF(B13="", "", IFERROR(INDEX(声優一覧!A:A, MATCH(B13, 声優一覧!B:B, 0)), "該当なし"))} -> va_004 | B13: 浅沼晋太郎 | C13: touken | D13: =IF(C13="", "", IFERROR(VLOOKUP(C13, 作品一覧!A:B, 2, FALSE), "該当なし")) -> 刀剣乱舞 | E13: 鳴狐
... A416: {=IF(B416="", "", IFERROR(INDEX(声優一覧!A:A, MATCH(B416, 声優一覧!B:B, 0)), "該当なし"))} -> va_112 | B416: 武内駿輔 | C416: aopl | D416: =IF(C416="", "", IFERROR(VLOOKUP(C416, 作品一覧!A:B, 2, FALSE), "該当なし")) -> アオペラ -aoppella!?- | E416: 伊佐良和
